Workbook
Name a_: #REF!
Name Arccos_x: Υπολογισμοί!#REF!
Name Arccos_x: [1]Sheet1!$A$7
Name cvTMP: Υπολογισμοί!#REF!
Name cvTMP: [1]Sheet1!$A$8
Name D_: #REF!
Name D_: #REF!
Name h_: #REF!
Name h_: #REF!
Name H_Cyl: Υπολογισμοί!#REF!
Name H_Cyl: [1]Sheet1!$D$7
Name H_HemiSphere: Υπολογισμοί!#REF!
Name H_HemiSphere: [1]Sheet1!$D$8
Name L_: #REF!
Name L_: #REF!
Name L_Cyl: Υπολογισμοί!#REF!
Name L_Cyl: [1]Sheet1!$D$6
Name R_: #REF!
Name R_: #REF!
Name R_Cyl: Υπολογισμοί!#REF!
Name R_Cyl: [1]Sheet1!$D$5
Name Radius: Υπολογισμοί!#REF!
Name Radius: [1]Sheet1!$A$5
Name X_: Υπολογισμοί!#REF!
Name X_: [1]Sheet1!$A$6

Sheet ΠΛΟΗΓΗΣΗ
A1: Ερασιτεχνικό Πρόγραμμα Κοινοχρήστων Πολυκατοικίας (για μέχρι 22 Διαμερίσματα & για 1 Χρόνο) | E1: Τα ΜΩΒ κελιά, σε μερικές Καρτέλες, είναι ΚΛΕΙΔΩΜΕΝΑ, σε αυτό το ΤΕΣΤ.
A2: Π Λ Ο Η Γ Η Σ Η
A3: Α/Α | B3: Απαιτούμενες Ενέργειες (Απαραίτητες κάθε Μήνα, όσες έχουν Κόκκινο Αριθμό) | C3: Πότε Χρειάζεται
A4: 1 | B4: Καταχώριση Στοιχείων Μηχανολόγου (Qολ-Qfi-Qai-Fεξi-Fπαρi & ύψος ορόφου) για Δημιουργία ή Έλεγχο Μηχανολογικής Μελέτης (fi & εi) & Αυτόνομης Θέρμανσης. | C4: Στην Αρχή, αν λείπουν ή το θέλετε
A5: =A4+1 -> 2 | B5: Ενημέρωση για τη Νομοθεσία: Κανονισμός Κατανομής Δαπανών Κεντρικής Θέρμανσης, Π.Δ. 27-9/7-11-85 (ΦΕΚ-631 Δ'). | C5: Αν θέλετε
A6: =A5+1 -> 3 | B6: Τροποποίηση (αν χρειάζεται) Κατηγοριών & Υποκατηγοριών Κοινόχρηστων Δαπανών (ΔΕΗ, Νερό, Καθαριότητα κλπ) στα Λευκά Κελιά του Πίνακα. | C6: Στην Αρχή & αν υπάρχει Αλλαγή
A7: =A6+1 -> 4 | B7: Καταχώριση Στοιχείων Διαμερισμάτων (Ιδιοκτήτης, Ένοικος, Εμβαδόν, Όροφος, Συντελεστές-Χιλιοστά κλπ) στα Λευκά Κελιά του Πίνακα. | C7: Στην Αρχή & όποτε υπάρχει Αλλαγή | E7: ΔΟΚΙΜΗ για 3 Διαμερίσματα.
A8: =A7+1 -> 5 | B8: Επιλογή Έτους & Μήνα Εκκίνησης, για την Παρακολούθηση & Εκτύπωση των Κοινοχρήστων μιας Πολυκατοικίας. | C8: Στην Αρχή & κάθε Χρόνο
A9: =A8+1 -> 6 | B9: Τροποποίηση-Καταχώριση Γενικών Στοιχείων (Διαχειριστής, Διεύθυνση, Πετρελαιάς κλπ) στα Πράσινα (ανοιχτά) Κελιά του Πίνακα. | C9: Στην Αρχή & όποτε υπάρχει Αλλαγή
A10: =A9+1 -> 7 | B10: Τροποποίηση-Καταχώριση Διαστάσεων Δεξαμενής Πετρελαίου στα Λευκά Κελιά του Πίνακα (πάνω αριστερά). | C10: Στην Αρχή μόνο
A11: =A10+1 -> 8 | B11: Τροποποίηση Στοιχείων Πρακτικού Παράδοσης-Παραλαβής Διαχείρισης (αν επιθυμείτε, για αποφυγή προβλημάτων) στα Λευκά Κελιά. | C11: Στην Αρχή, ο Νέος Διαχειριστής
A12: =A11+1 -> 9 | B12: Τροποποίηση-Δημιουργία Απολογισμού, για την Ετήσια Συνέλευση Ιδιοκτητών-Ενοικιαστών. | C12: Κάθε Χρόνο, αν το θέλετε
A13: =A12+1 -> 10 | B13: Στην Καρτέλα "Θέρμανση", Υπολογίζεται η Αυτόνομη Θέρμανση, δηλαδή η Κατανομή του Πετρελαίου βάσει των Ωρών. | C13: Το Παλιό Περιβόητο 30%
A14: =A13+1 -> 11 | B14: Τροποποίηση-Δημιουργία Ετήσιων Πινάκων Εξόδων-Εσόδων & Γραφήματος Εξόδων, για παρουσίαση στην Ετήσια Συνέλευση. | C14: Κάθε Χρόνο, αν το θέλετε
A15: =A14+1 -> 12 | B15: Τροποποίηση-Καταχώριση Στοιχείων Επισκέψεων Συντηρητή Ανελκυστήρα, για Έλεγχο τυχόν Εκκρεμοτήτων. | C15: Όποτε & αν θέλετε
A16: =A15+1 -> 13 | B16: Τροποποίηση-Δημιουργία Πίνακα για κάτι Έκτακτο, όπως π.χ. για την Ομαδική Τοποθέτηση "Καπέλων" Καμινάδων Τζακιών. | C16: Όποτε & αν χρειαστεί
A17: =A16+1 -> 14 | B17: Καταχώριση Στοιχείων Παραλαβής Πετρελαίου (αν υπάρχει) & Καταχώρηση Ύψους Δεξαμενής Πετρελαίου στις 28 του μήνα. | C17: Στο Τέλος κάθε Μήνα | E17: ΔΟΚΙΜΗ για 5 Καταχωρήσεις.
A18: =A17+1 -> 15 | B18: Καταχώριση Ενδείξεων Ωρομετρητών Αυτόνομης Θέρμανσης στις 28 του μήνα. | C18: Στο Τέλος κάθε Μήνα | E18: ΔΟΚΙΜΗ για 2 Μήνες.
A19: =A18+1 -> 16 | B19: Καταχώριση Κοινόχρηστων Δαπανών του μήνα που τελειώνει, στα Λευκά Κελιά του μεσαίου Πίνακα. | C19: Κάθε Μήνα | E19: ΔΟΚΙΜΗ για 2 Μήνες.
A20: =A19+1 -> 17 | B20: Καταχώριση Σχολίων-Πληροφοριών προς τους Ενοίκους, που θα εμφανίζονται στις 2 τελευταίες σειρές του Μηνιαίου Εντύπου Κοινοχρήστων. | C20: Κάθε Μήνα, αν το θέλετε
A21: =A20+1 -> 18 | B21: Καταχώριση Αναλυτικής Ενημέρωσης προς τους Ενοίκους, που θα Εκτυπώνετε στο πίσω μέρος του Μηνιαίου Εντύπου Κοινοχρήστων. | C21: Όποιο Μήνα θέλετε
A22: =A21+1 -> 19 | B22: Καταχώριση Προβλεπόμενων ΕΣΟΔΩΝ & ΕΞΟΔΩΝ στο Ταμείο Διαχείρισης Πολυκατοικίας & Τσεκάρισμα όταν Ολοκληρώνονται. | C22: Για κάθε Έσοδο ή Έξοδο
A23: =A22+1 -> 20 | B23: Τροποποίηση-Καταχώριση Αναλυτικά των Εξόδων για Αναλώσιμα Υλικά & ότι δεν περιλαμβάνεται στις άλλες Κατηγορίες Δαπανών. | C23: Για κάθε Αναλώσιμο, αν θέλετε
A24: =A23+1 -> 21 | B24: Μετακίνηση στην Έντυπη Κατάσταση Συνολικών Μηνιαίων Κοινοχρήστων, (ανά Ένοικο), για ΕΚΤΥΠΩΣΗ, για τον Πίνακα Ανακοινώσεων. | C24: Στο Τέλος κάθε Μήνα
A25: =A24+1 -> 22 | B25: Μετακίνηση στις Καρτέλες με τα Ατομικά Μηνιαία Κοινόχρηστα των Ενοίκων, για ΕΚΤΥΠΩΣΗ, για τα Διαμερίσματα 1&2. | C25: Στο Τέλος κάθε Μήνα
A26: =A25+1 -> 23 | B26: Μετακίνηση στις Καρτέλες με τα Ατομικά Μηνιαία Κοινόχρηστα των Ενοίκων, για ΕΚΤΥΠΩΣΗ, για τα Διαμερίσματα 3&4. | C26: Στο Τέλος κάθε Μήνα
A27: =A26+1 -> 24 | B27: Μετακίνηση στις Καρτέλες με τα Ατομικά Μηνιαία Κοινόχρηστα των Ενοίκων, για ΕΚΤΥΠΩΣΗ, για τα Διαμερίσματα 5&6. | C27: Στο Τέλος κάθε Μήνα
A28: =A27+1 -> 25 | B28: Μετακίνηση στις Καρτέλες με τα Ατομικά Μηνιαία Κοινόχρηστα των Ενοίκων, για ΕΚΤΥΠΩΣΗ, για τα Διαμερίσματα 7&8. | C28: Στο Τέλος κάθε Μήνα
A29: =A28+1 -> 26 | B29: Μετακίνηση στις Καρτέλες με τα Ατομικά Μηνιαία Κοινόχρηστα των Ενοίκων, για ΕΚΤΥΠΩΣΗ, για τα Διαμερίσματα 9&10 κλπ. | C29: Στο Τέλος κάθε Μήνα
A30: =A29+1 -> 27 | B30: Μετακίνηση στην Καρτέλα με την Αναλυτική Ενημέρωση προς τους Ενοίκους, για ΕΚΤΥΠΩΣΗ, πίσω από το Μηνιαίο Έντυπο Κοινοχρήστων. | C30: Όποιο Μήνα θέλετε
A32: Μετά τον 1ο Χρόνο, δημιουργήστε Αντίγραφο του αρχείου Excel & επιλέξτε Νέο Έτος και Μήνα Εκκίνησης.
A34: 1 | B34: για Μηνιαία Καταχώριση Στοιχείων ……………………………………………………………………………………….. | C34: Κόκκινες Καρτέλες
A35: 2 | B35: για Εκτύπωση Μηνιαίων Κοινοχρήστων …………………………………………………………………………………. | C35: Μπλε Καρτέλες
A36: 3 | B36: για Αρχική Καταχώριση Στοιχείων ………………………………………………………………………………………….. | C36: Πράσινες Καρτέλες
A37: 4 | B37: αν χρειαστούν & Βοηθητικά ή για Ενημέρωση ….…………………………………………………………………… | C37: Γκρι Καρτέλες
A39: ..… & λίγη Φ Λ Υ Α Ρ Ι Α ..…
A40: Το παρακάτω κείμενο, το έγραψα σε Φόρουμ Λίνουξ, που αναζητούσαν πρόγραμμα Κοινοχρήστων: Για Κοινόχρηστα σε windows υπάρχει το πρόγραμμα του RAM, είναι ΔΩΡΕΑΝ, αλλά έχει περιορισμένες δυνατότητες. Διαφορετικά πρέπει να το αγοράσεις από την εταιρεία που το έφτιαξε (αν θυμάμαι ~100 ευρώ) και συνήθως πρέπει να πληρώνεις για κάθε αλλαγή. Έψαξα και εγώ πάρα πολύ, (γιατί με ψήφισαν για Διαχειριστή), αγανάκτησα γιατί δεν έβρισκα ολοκληρωμένη λογική λύση & για άπειρα επιπλέον προβλήματα, όπως ζητήματα Συντελεστών (ορθότητα χιλιοστών), παρακολούθησης Πετρελαίου, Ωρομετρητών, ελέγχου-δημιουργίας Μηχανολογικής Μελέτης, υπολογισμού fi & εi για (Αυτόνομη Θέρμανση), Ταμείου Διαχείρισης (& αναλώσιμων), Ανελκυστήρα, Αποθεματικού, εισαγωγής Σχολίων (για Ενοίκους) κλπ και: Αποφάσισα & "χτύπησα" πολλά (πάρα πολλά) 15ωρα, επί 1,5 μήνα (συνταξιούχος ων) και έφτιαξα στο Excel-2007, ΤΟ πρόγραμμα Κοινοχρήστων κλπ (για 10 διαμερίσματα), πλήρως παραμετροποιήσιμο, έγινα "σούπερ" Διαχειριστής (με πολλές καινοτομίες & κυρίως Απόλυτη ΔΙΑΦΑΝΕΙΑ, ακόμη & μέσω Internet με ειδικό site) και τους ΧΡΕΩΝΩ 20 ευρώ το μήνα για την έκδοση Κοινοχρήστων και 60 ευρώ το μήνα για τη Διαχείριση. Σε 1 χρόνο, έκανα Απολογισμό στη Συνέλευση των Ενοίκων για αλλαγή Διαχειριστή, με μείωση των δαπανών Ανελκυστήρα (50%) & ΔΕΗ (60%), υπερκαλύπτοντας τις αμοιβές μου και τις δαπάνες αναλωσίμων (κυρίως Οικονομικούς Λαμπτήρες-Προβολάκια-LED, Πυροσβεστήρες 2 ετών, Ανιχνευτή CO κλπ, καθώς & διάφορες πατέντες). "Και φυσικά το ετήσιο όφελος θα υπάρχει και τα επόμενα χρόνια." Ζήτησα να αναλάβει ο επόμενος ετήσιος Διαχειριστής, αλλά "ΔΥΣΤΥΧΩΣ" με ξαναψήφισαν ομόφωνα και με πρότειναν & σε 3 ακόμη Πολυκατοικίες (που ανέλαβα τελικά με 20 ευρώ επιπλέον). Αρκετά σας ΖΑΛΙΣΑ όμως. Δοκίμασα να μετατρέψω ένα προγραμματάκι, (που έκανα πέρυσι σε Excel για εκμάθηση Προπαίδειας), για χρήση σε Linux και διαπίστωσα ότι παρουσιάζονται προβλήματα στις Συναρτήσεις. Οπότε για τα Κοινόχρηστα, με πολλαπλάσιες & πιό σύνθετες Συναρτήσεις, δεν τόλμησα να κάνω μετατροπή. Με εκτίμηση, Φώτης.
A41: Το ένα χέρι νίβει το άλλο και τα δυό το πρόσωπο. Γιατί κάθε φορά και ο καθένας μας να ανακαλύπτει εξ' αρχής τον τροχό ; Ζούμε στην εποχή της πληροφορικής και κυρίως της πληροφορίας. Η σωστή πληροφορία, την κατάλληλη στιγμή, είναι δύναμη. Τώρα λοιπόν, που έχουμε αυτό το ΚΑΤΑΠΛΗΚΤΙΚΟ εργαλείο που λέγεται ΙΝΤΕΡΝΕΤ, έχουμε τη δυνατότητα να καταθέτει ο καθένας μας τις ιδέες, τις γνώσεις και τις προτάσεις του, με αποτέλεσμα να δημιουργούμε τον μεγαλύτερο πλούτο πληροφοριών που υπήρξε ποτέ. Ταυτόχρονα, έχουμε όλοι τη δυνατότητα, να κάνουμε κτήμα μας αυτόν τον πλούτο ΔΩΡΕΑΝ, με σημαντικότατα κέρδη όπως, εξοικονόμηση χρόνου και χρήματος, βελτίωση της υγείας μας, των γνώσεών μας, της εργασίας μας και των συνθηκών της ζωής μας γενικότερα, προστασία του περιβάλλοντος και της ελεύθερης διακίνησης των ιδεών κλπ κλπ. http://dorean-free.blogspot.com Αυτό το ΕΡΑΣΙΤΕΧΝΙΚΟ προγραμματάκι Κοινοχρήστων, είναι μια μικρή δική μου συμβολή στην κοινή προσπάθεια & θα το βρίσκετε στη Διεύθυνση: http://spiti.ofotis.operaunite.com/arhia Με εκτίμηση, Τσιρίδης Φώτης, ofotis@gmail.com ( http://ofotis.blogspot.com ).
A42: Φυσικά υπάρχουν οι Επαγγελματικές λύσεις, με υψηλές προδιαγραφές, για όποιον θέλει, όπως: www.poseidon.gr/proionta/kinoxrista & www.e-diaxeirisi.gr & achaia.building.services & www.toktirio.gr κλπ

Sheet Ταμείο
A1: ΤΑΜΕΙΟ ΔΙΑΧΕΙΡΙΣΗΣ ΠΟΛΥΚΑΤΟΙΚΙΑΣ | D1: =ΣΤΟΙΧΕΙΑ!C12 -> Διευθύνση 123
A2: Με την Απόφαση της Συνέλευσης των Ενοίκων της Πολυκατοικίας, που έγινε στις ….../..…/2010, Παρέλαβε τη Διαχείριση ο κ.Φ.Διαχειριστίδης.
A3: Αναλαμβάνει να Εισπράττει τα Κοινόχρηστα, από τους Ενοίκους της Πολυκατοικίας, από το μήνα Ιανουάριο του 2009, συμπεριλαμβανομένου.
A4: Υποχρεούται επίσης να Πληρώνει τις Δαπάνες των Κοινοχρήστων της Πολυκατοικίας, από τον ίδιο μήνα, συμπεριλαμβανομένου.
A5: Με την Παραλαβή της Διαχείρισης, στις ….../..…/2010, θα εισπράξει το Πάγιο-Αποθεματικό 1.000 €, που πλήρωσαν οι Ένοικοι στον προηγούμενο Διαχειριστή.
A6: Τέλος, ο Νέος Διαχειριστής, οφείλει να Πληρώσει στον προηγούμενο Διαχειριστή, το υπόλοιπο της Δεξαμενής, ύψους 40 cm, (342 € απλήρωτα από 28-12-2008).
A7: Α/Α | B7: Ημερομηνία | C7: Περιγραφή Οικονομικών Δοσοληψιών Διαχείρισης | D7: Προβλεπόμενα | G7: ΝΑΙ | H7: Ολοκληρωμένα | L7: =ΣΤΟΙΧΕΙΑ!C3 -> Κ Ο Ι Ν Ο Χ Ρ Η Σ Τ Α :
D8: Έσοδα | E8: Έξοδα | F8: Υπόλοιπο | G8: ΟΧΙ | H8: Έσοδα | I8: Έξοδα | J8: Υπόλοιπο | L8: =ΣΤΟΙΧΕΙΑ!C11 -> 40878
A9: 1 | B9: 39841 | C9: Από Οφειλόμενα των Ενοίκων για το Υπόλοιπο Πετρέλαιο Δεξαμενής των 80 cm (-1 Στρογγυλ.) | D9: 194 | F9: =D9-E9 -> 194 | G9: ΟΧΙ | H9: =IF(D9="","",IF($G9="","",IF($G9="ΟΧΙ","",D9))) | I9: =IF(E9="","",IF($G9="","",IF($G9="ΟΧΙ","",E9))) | J9: =IF(AND(H9="",I9=""),0,IF(H9="",-I9,H9)) -> 0 | L9: Επιστροφή στην ΠΛΟΗΓΗΣΗ
A10: =A9+1 -> 2 | B10: ΠΑΡΑΔΟΣΗ | C10: Οφειλή ΠΑΓΙΟΥ-αποθεματικού, σε Επόμ.Διαχειριστή ή σε Ενοίκους Πολυκατοικίας (1.000+200) | E10: 1200 | F10: =F9+D10-E10 -> -1006 | G10: ΟΧΙ | H10: =IF(D10="","",IF($G10="","",IF($G10="ΟΧΙ","",D10))) | I10: =IF(E10="","",IF($G10="","",IF($G10="ΟΧΙ","",E10))) | J10: =IF(AND(H10="",I10=""),J9,IF(H10="",J9-I10,J9+H10)) -> 0
A11: =A10+1 -> 3 | B11: 39813 | C11: Από προηγούμενο Διαχειριστή, Πάγιο-Αποθεματικό Πολυκατοικίας, στο Νέο Διαχειριστή | D11: 1000 | F11: =F10+D11-E11 -> -6 | G11: ΝΑΙ | H11: =IF(D11="","",IF($G11="","",IF($G11="ΟΧΙ","",D11))) -> 1000 | I11: =IF(E11="","",IF($G11="","",IF($G11="ΟΧΙ","",E11))) | J11: =IF(AND(H11="",I11=""),J10,IF(H11="",J10-I11,J10+H11)) -> 1000
A12: =A11+1 -> 4 | B12: 39813 | C12: Σε προηγούμενο Διαχ/στή για Υφιστάμενο Πετρέλαιο Δεξαμενής 40 cm, (απλήρωτο από 28-12-08) | E12: 342 | F12: =F11+D12-E12 -> -348 | G12: ΝΑΙ | H12: =IF(D12="","",IF($G12="","",IF($G12="ΟΧΙ","",D12))) | I12: =IF(E12="","",IF($G12="","",IF($G12="ΟΧΙ","",E12))) -> 342 | J12: =IF(AND(H12="",I12=""),J11,IF(H12="",J11-I12,J11+H12)) -> 658
A13: =A12+1 -> 5 | B13: …………… | C13: Πληρωμή Λογαριασμού ΔΕΗ-κοινοχρήστων μέχρι 19-1-2009, (ΕΝΑΝΤΙ) | E13: 150 | F13: =F12+D13-E13 -> -498 | G13: ΝΑΙ | H13: =IF(D13="","",IF($G13="","",IF($G13="ΟΧΙ","",D13))) | I13: =IF(E13="","",IF($G13="","",IF($G13="ΟΧΙ","",E13))) -> 150 | J13: =IF(AND(H13="",I13=""),J12,IF(H13="",J12-I13,J12+H13)) -> 508
A14: =A13+1 -> 6 | B14: …………… | C14: Πληρωμή Συντηρητή Ανελκυστήρα, για τον Ιανουάριο 2009 | E14: 55 | F14: =F13+D14-E14 -> -553 | G14: ΝΑΙ | H14: =IF(D14="","",IF($G14="","",IF($G14="ΟΧΙ","",D14))) | I14: =IF(E14="","",IF($G14="","",IF($G14="ΟΧΙ","",E14))) -> 55 | J14: =IF(AND(H14="",I14=""),J13,IF(H14="",J13-I14,J13+H14)) -> 453
A15: =A14+1 -> 7 | B15: …………… | C15: Πληρωμή Αναλώσιμων (Πυροσβεστήρας, Σκάλα, Μικροεξαρτήματα, Οικονομικές Λάμπες κλπ) | E15: 75 | F15: =F14+D15-E15 -> -628 | G15: ΝΑΙ | H15: =IF(D15="","",IF($G15="","",IF($G15="ΟΧΙ","",D15))) | I15: =IF(E15="","",IF($G15="","",IF($G15="ΟΧΙ","",E15))) -> 75 | J15: =IF(AND(H15="",I15=""),J14,IF(H15="",J14-I15,J14+H15)) -> 378
A16: =A15+1 -> 8 | B16: …………… | C16: Πληρωμή Συντηρητή Κήπου, για τον Ιανουάριο 2009 | E16: 60 | F16: =F15+D16-E16 -> -688 | G16: ΝΑΙ | H16: =IF(D16="","",IF($G16="","",IF($G16="ΟΧΙ","",D16))) | I16: =IF(E16="","",IF($G16="","",IF($G16="ΟΧΙ","",E16))) -> 60 | J16: =IF(AND(H16="",I16=""),J15,IF(H16="",J15-I16,J15+H16)) -> 318
A17: =A16+1 -> 9 | B17: …………… | C17: Πληρωμή Καθαρίστριας, για τον Ιανουάριο 2009 | E17: 70 | F17: =F16+D17-E17 -> -758 | G17: ΝΑΙ | H17: =IF(D17="","",IF($G17="","",IF($G17="ΟΧΙ","",D17))) | I17: =IF(E17="","",IF($G17="","",IF($G17="ΟΧΙ","",E17))) -> 70 | J17: =IF(AND(H17="",I17=""),J16,IF(H17="",J16-I17,J16+H17)) -> 248
A18: =A17+1 -> 10 | B18: …………… | C18: Πληρωμή Έκδοσης Κοινοχρήστων, για τον Ιανουάριο 2009 | E18: 20 | F18: =F17+D18-E18 -> -778 | G18: ΝΑΙ | H18: =IF(D18="","",IF($G18="","",IF($G18="ΟΧΙ","",D18))) | I18: =IF(E18="","",IF($G18="","",IF($G18="ΟΧΙ","",E18))) -> 20 | J18: =IF(AND(H18="",I18=""),J17,IF(H18="",J17-I18,J17+H18)) -> 228
A19: =A18+1 -> 11 | B19: …………… | C19: Πληρωμή Διαχειριστή, για τον Ιανουάριο 2009 | E19: 60 | F19: =F18+D19-E19 -> -838 | G19: ΝΑΙ | H19: =IF(D19="","",IF($G19="","",IF($G19="ΟΧΙ","",D19))) | I19: =IF(E19="","",IF($G19="","",IF($G19="ΟΧΙ","",E19))) -> 60 | J19: =IF(AND(H19="",I19=""),J18,IF(H19="",J18-I19,J18+H19)) -> 168
A20: =A19+1 -> 12 | B20: …………… | C20: Πληρωμή Κοινόχρηστου-ΝΕΡΟΥ μέχρι 10-1-2009 | E20: 30 | F20: =F19+D20-E20 -> -868 | G20: ΝΑΙ | H20: =IF(D20="","",IF($G20="","",IF($G20="ΟΧΙ","",D20))) | I20: =IF(E20="","",IF($G20="","",IF($G20="ΟΧΙ","",E20))) -> 30 | J20: =IF(AND(H20="",I20=""),J19,IF(H20="",J19-I20,J19+H20)) -> 138 | L20: =SUM(E13:E20)+ΣΤΟΙΧΕΙΑ!G31+ΣΤΟΙΧΕΙΑ!G34 -> 520
A21: =A20+1 -> 13 | C21: Από Είσπραξη Κοινοχρήστων Ιανουαρίου 2009. Ένοικος: Ιδιοκτήτης-1, Α1 | D21: 53 | F21: =F20+D21-E21 -> -815 | G21: ΟΧΙ | H21: =IF(D21="","",IF($G21="","",IF($G21="ΟΧΙ","",D21))) | I21: =IF(E21="","",IF($G21="","",IF($G21="ΟΧΙ","",E21))) | J21: =IF(AND(H21="",I21=""),J20,IF(H21="",J20-I21,J20+H21)) -> 138 | L21: =Διαμερίσματα!$AB6 -> 44.314208 | M21: =ROUND(L21,0) -> 44 | N21: ΑΝΤΕΓΡΑΨΕ ΤΑ ΚΕΛΙΑ ΑΡΙΣΤΕΡΑ
A22: =A21+1 -> 14 | C22: Από Είσπραξη Κοινοχρήστων Ιανουαρίου 2009. Ένοικος: Ιδιοκτήτης-2, Α2 | D22: 113 | F22: =F21+D22-E22 -> -702 | G22: ΟΧΙ | H22: =IF(D22="","",IF($G22="","",IF($G22="ΟΧΙ","",D22))) | I22: =IF(E22="","",IF($G22="","",IF($G22="ΟΧΙ","",E22))) | J22: =IF(AND(H22="",I22=""),J21,IF(H22="",J21-I22,J21+H22)) -> 138 | L22: =Διαμερίσματα!$AB7 -> 49.190348 | M22: =ROUND(L22,0) -> 49
A23: =A22+1 -> 15 | B23: …………… | C23: Από Είσπραξη Κοινοχρήστων Ιανουαρίου 2009. Ένοικος: Ιδιοκτήτης-3, Α3 | D23: 146 | F23: =F22+D23-E23 -> -556 | G23: ΝΑΙ | H23: =IF(D23="","",IF($G23="","",IF($G23="ΟΧΙ","",D23))) -> 146 | I23: =IF(E23="","",IF($G23="","",IF($G23="ΟΧΙ","",E23))) | J23: =IF(AND(H23="",I23=""),J22,IF(H23="",J22-I23,J22+H23)) -> 284 | L23: =Διαμερίσματα!$AB8 -> 225.03995 | M23: =ROUND(L23,0) -> 225
A24: =A23+1 -> 16 | C24: Από Είσπραξη Κοινοχρήστων Ιανουαρίου 2009. Ένοικος: Ιδιοκτήτης-4, Β1 | D24: 156 | F24: =F23+D24-E24 -> -400 | G24: ΟΧΙ | H24: =IF(D24="","",IF($G24="","",IF($G24="ΟΧΙ","",D24))) | I24: =IF(E24="","",IF($G24="","",IF($G24="ΟΧΙ","",E24))) | J24: =IF(AND(H24="",I24=""),J23,IF(H24="",J23-I24,J23+H24)) -> 284 | L24: =Διαμερίσματα!$AB9 -> 178.03119 | M24: =ROUND(L24,0) -> 178
A25: =A24+1 -> 17 | B25: …………… | C25: Από Είσπραξη Κοινοχρήστων Ιανουαρίου 2009. Ένοικος: Ιδιοκτήτης-5, Β2 | D25: 155 | F25: =F24+D25-E25 -> -245 | G25: ΝΑΙ | H25: =IF(D25="","",IF($G25="","",IF($G25="ΟΧΙ","",D25))) -> 155 | I25: =IF(E25="","",IF($G25="","",IF($G25="ΟΧΙ","",E25))) | J25: =IF(AND(H25="",I25=""),J24,IF(H25="",J24-I25,J24+H25)) -> 439 | L25: =Διαμερίσματα!$AB10 -> 164.47441 | M25: =ROUND(L25,0) -> 164
A26: =A25+1 -> 18 | B26: …………… | C26: Από Είσπραξη Κοινοχρήστων Ιανουαρίου 2009. Ένοικος: Ιδιοκτήτης-6, Β3 | D26: 51 | F26: =F25+D26-E26 -> -194 | G26: ΝΑΙ | H26: =IF(D26="","",IF($G26="","",IF($G26="ΟΧΙ","",D26))) -> 51 | I26: =IF(E26="","",IF($G26="","",IF($G26="ΟΧΙ","",E26))) | J26: =IF(AND(H26="",I26=""),J25,IF(H26="",J25-I26,J25+H26)) -> 490 | L26: =Διαμερίσματα!$AB11 -> 29.674312 | M26: =ROUND(L26,0) -> 30
A27: =A26+1 -> 19 | C27: Από Είσπραξη Κοινοχρήστων Ιανουαρίου 2009. Ένοικος: Ενοικιαστής-7, Γ1 | D27: 46 | F27: =F26+D27-E27 -> -148 | G27: ΟΧΙ | H27: =IF(D27="","",IF($G27="","",IF($G27="ΟΧΙ","",D27))) | I27: =IF(E27="","",IF($G27="","",IF($G27="ΟΧΙ","",E27))) | J27: =IF(AND(H27="",I27=""),J26,IF(H27="",J26-I27,J26+H27)) -> 490 | L27: =Διαμερίσματα!$AB12 -> 78.11043 | M27: =ROUND(L27,0) -> 78
A28: =A27+1 -> 20 | C28: Από Είσπραξη Κοινοχρήστων Ιανουαρίου 2009. Ένοικος: Ιδιοκτήτης-8, Γ2 | D28: 84 | F28: =F27+D28-E28 -> -64 | G28: ΟΧΙ | H28: =IF(D28="","",IF($G28="","",IF($G28="ΟΧΙ","",D28))) | I28: =IF(E28="","",IF($G28="","",IF($G28="ΟΧΙ","",E28))) | J28: =IF(AND(H28="",I28=""),J27,IF(H28="",J27-I28,J27+H28)) -> 490 | L28: =Διαμερίσματα!$AB13 -> 77.398602 | M28: =ROUND(L28,0) -> 77
A29: =A28+1 -> 21 | C29: Από Είσπραξη Κοινοχρήστων Ιανουαρίου 2009. Ένοικος: Ιδιοκτήτης-9, Γ3 | D29: 87 | F29: =F28+D29-E29 -> 23 | G29: ΟΧΙ | H29: =IF(D29="","",IF($G29="","",IF($G29="ΟΧΙ","",D29))) | I29: =IF(E29="","",IF($G29="","",IF($G29="ΟΧΙ","",E29))) | J29: =IF(AND(H29="",I29=""),J28,IF(H29="",J28-I29,J28+H29)) -> 490 | L29: =Διαμερίσματα!$AB14 -> 133.28129 | M29: =ROUND(L29,0) -> 133
A30: =A29+1 -> 22 | B30: …………… | C30: Από Είσπραξη Κοινοχρήστων Ιανουαρίου 2009. Ένοικος: Ιδιοκτήτης-10, Δ1 | D30: 140 | F30: =F29+D30-E30 -> 163 | G30: ΝΑΙ | H30: =IF(D30="","",IF($G30="","",IF($G30="ΟΧΙ","",D30))) -> 140 | I30: =IF(E30="","",IF($G30="","",IF($G30="ΟΧΙ","",E30))) | J30: =IF(AND(H30="",I30=""),J29,IF(H30="",J29-I30,J29+H30)) -> 630 | L30: =Διαμερίσματα!$AB15 -> 236.65566 | M30: =ROUND(L30,0) -> 237
A31: =A30+1 -> 23 | C31: Από Είσπραξη Κοινοχρήστων Ιανουαρίου 2009. Ένοικος: Ιδιοκτήτης-11, Δ2 | D31: 81 | F31: =F30+D31-E31 -> 244 | G31: ΟΧΙ | H31: =IF(D31="","",IF($G31="","",IF($G31="ΟΧΙ","",D31))) | I31: =IF(E31="","",IF($G31="","",IF($G31="ΟΧΙ","",E31))) | J31: =IF(AND(H31="",I31=""),J30,IF(H31="",J30-I31,J30+H31)) -> 630 | L31: =Διαμερίσματα!$AB16 -> 0 | M31: =ROUND(L31,0) -> 0
A32: =A31+1 -> 24 | B32: …………… | C32: Από Είσπραξη Κοινοχρήστων Ιανουαρίου 2009. Ένοικος: Ιδιοκτήτης-12, Δ3 | D32: 36 | F32: =F31+D32-E32 -> 280 | H32: =IF(D32="","",IF($G32="","",IF($G32="ΟΧΙ","",D32))) | I32: =IF(E32="","",IF($G32="","",IF($G32="ΟΧΙ","",E32))) | J32: =IF(AND(H32="",I32=""),J31,IF(H32="",J31-I32,J31+H32)) -> 630 | L32: =Διαμερίσματα!$AB17 -> 26.341334 | M32: =ROUND(L32,0) -> 26
A33: =A32+1 -> 25 | C33: Από Είσπραξη Κοινοχρήστων Ιανουαρίου 2009. Ένοικος: Ιδιοκτήτης-13, Δ4 | D33: 37 | F33: =F32+D33-E33 -> 317 | G33: ΟΧΙ | H33: =IF(D33="","",IF($G33="","",IF($G33="ΟΧΙ","",D33))) | I33: =IF(E33="","",IF($G33="","",IF($G33="ΟΧΙ","",E33))) | J33: =IF(AND(H33="",I33=""),J32,IF(H33="",J32-I33,J32+H33)) -> 630 | L33: =Διαμερίσματα!$AB18 -> 26.371227 | M33: =ROUND(L33,0) -> 26
A34: =A33+1 -> 26 | C34: Από Είσπραξη Κοινοχρήστων Ιανουαρίου 2009. Ένοικος: Ιδιοκτήτης-14, Δ5 | D34: 36 | F34: =F33+D34-E34 -> 353 | H34: =IF(D34="","",IF($G34="","",IF($G34="ΟΧΙ","",D34))) | I34: =IF(E34="","",IF($G34="","",IF($G34="ΟΧΙ","",E34))) | J34: =IF(AND(H34="",I34=""),J33,IF(H34="",J33-I34,J33+H34)) -> 630 | L34: =Διαμερίσματα!$AB19 -> 26.371227 | M34: =ROUND(L34,0) -> 26
A35: =A34+1 -> 27 | C35: Από Είσπραξη Κοινοχρήστων Ιανουαρίου 2009. Ένοικος: Ιδιοκτήτης-15, Δ6 | D35: 37 | F35: =F34+D35-E35 -> 390 | H35: =IF(D35="","",IF($G35="","",IF($G35="ΟΧΙ","",D35))) | I35: =IF(E35="","",IF($G35="","",IF($G35="ΟΧΙ","",E35))) | J35: =IF(AND(H35="",I35=""),J34,IF(H35="",J34-I35,J34+H35)) -> 630 | L35: =Διαμερίσματα!$AB20 -> 26.371227 | M35: =ROUND(L35,0) -> 26
A36: =A35+1 -> 28 | C36: Από Είσπραξη Κοινοχρήστων Ιανουαρίου 2009. Ένοικος: Ιδιοκτήτης-16, Δ7 | D36: 36 | F36: =F35+D36-E36 -> 426 | H36: =IF(D36="","",IF($G36="","",IF($G36="ΟΧΙ","",D36))) | I36: =IF(E36="","",IF($G36="","",IF($G36="ΟΧΙ","",E36))) | J36: =IF(AND(H36="",I36=""),J35,IF(H36="",J35-I36,J35+H36)) -> 630 | L36: =Διαμερίσματα!$AB21 -> 26.371227 | M36: =ROUND(L36,0) -> 26
A37: =A36+1 -> 29 | C37: Από Είσπραξη Κοινοχρήστων Ιανουαρίου 2009. Ένοικος: Ιδιοκτήτης-17, Δ8 | D37: 37 | F37: =F36+D37-E37 -> 463 | H37: =IF(D37="","",IF($G37="","",IF($G37="ΟΧΙ","",D37))) | I37: =IF(E37="","",IF($G37="","",IF($G37="ΟΧΙ","",E37))) | J37: =IF(AND(H37="",I37=""),J36,IF(H37="",J36-I37,J36+H37)) -> 630 | L37: =Διαμερίσματα!$AB22 -> 26.371227 | M37: =ROUND(L37,0) -> 26
A38: =A37+1 -> 30 | C38: Από Είσπραξη Κοινοχρήστων Ιανουαρίου 2009. Ένοικος: Ιδιοκτήτης-18, Δ9 | D38: 36 | F38: =F37+D38-E38 -> 499 | H38: =IF(D38="","",IF($G38="","",IF($G38="ΟΧΙ","",D38))) | I38: =IF(E38="","",IF($G38="","",IF($G38="ΟΧΙ","",E38))) | J38: =IF(AND(H38="",I38=""),J37,IF(H38="",J37-I38,J37+H38)) -> 630 | L38: =Διαμερίσματα!$AB23 -> 26.518445 | M38: =ROUND(L38,0) -> 27
A39: =A38+1 -> 31 | C39: Από Είσπραξη Κοινοχρήστων Ιανουαρίου 2009. Ένοικος: Ιδιοκτήτης-19, Δ10 | D39: 37 | F39: =F38+D39-E39 -> 536 | H39: =IF(D39="","",IF($G39="","",IF($G39="ΟΧΙ","",D39))) | I39: =IF(E39="","",IF($G39="","",IF($G39="ΟΧΙ","",E39))) | J39: =IF(AND(H39="",I39=""),J38,IF(H39="",J38-I39,J38+H39)) -> 630 | L39: =Διαμερίσματα!$AB24 -> 26.371227 | M39: =ROUND(L39,0) -> 26
A40: =A39+1 -> 32 | C40: Από Είσπραξη Κοινοχρήστων Ιανουαρίου 2009. Ένοικος: Ιδιοκτήτης-20, Δ11 | D40: 36 | F40: =F39+D40-E40 -> 572 | H40: =IF(D40="","",IF($G40="","",IF($G40="ΟΧΙ","",D40))) | I40: =IF(E40="","",IF($G40="","",IF($G40="ΟΧΙ","",E40))) | J40: =IF(AND(H40="",I40=""),J39,IF(H40="",J39-I40,J39+H40)) -> 630 | L40: =Διαμερίσματα!$AB25 -> 26.371227 | M40: =ROUND(L40,0) -> 26
...

Sheet Σύνολα
A1: 1 | C1: =ΣΤΟΙΧΕΙΑ!C3 -> Κ Ο Ι Ν Ο Χ Ρ Η Σ Τ Α :
C2: =ΣΤΟΙΧΕΙΑ!C12 -> Διευθύνση 123
C3: =ΣΤΟΙΧΕΙΑ!C11 -> 40878
C4: Κάηκαν | D4: =IFERROR(VLOOKUP(C3,Πετρέλαιο!$B$13:$V$33,20,FALSE),0) -> 840.6 | E4: =IFERROR(VLOOKUP(C3,Πετρέλαιο!$B$13:$V$33,21,FALSE),0) -> 700 | F4: μέχρι τέλος | T4: =ΣΤΟΙΧΕΙΑ!C10 -> 40878
C5: Νέο Ύψος Δεξαμενής | E5: =IFERROR(VLOOKUP(C3,Πετρέλαιο!$B$13:$V$33,18,FALSE),0) -> 15 | F5: Απλήρωτο | T5: =(IFERROR(VLOOKUP(C3,Πετρέλαιο!$B$13:$V$33,10,FALSE),0))-(IFERROR(VLOOKUP(C3,Πετρέλαιο!$B$13:$V$33,21,FALSE),0)) -> 390
A6: Α/Α | B6: Διαμέρισμα | C6: Ένοικος | F6: Ώρες | G6: =INDIRECT(ADDRESS(A7,6,3,,"ΣΤΟΙΧΕΙΑ")) -> 40848 | H6: =INDIRECT(ADDRESS(B7,6,3,,"ΣΤΟΙΧΕΙΑ")) -> 40878 | I6: =INDIRECT(ADDRESS(C7,6,3,,"ΣΤΟΙΧΕΙΑ")) -> 40909 | J6: =INDIRECT(ADDRESS(G7,6,3,,"ΣΤΟΙΧΕΙΑ")) -> 41061 | K6: =INDIRECT(ADDRESS(H7,6,3,,"ΣΤΟΙΧΕΙΑ")) -> 41091 | L6: =INDIRECT(ADDRESS(I7,6,3,,"ΣΤΟΙΧΕΙΑ")) -> 41122 | M6: =INDIRECT(ADDRESS(J7,6,3,,"ΣΤΟΙΧΕΙΑ")) -> 41153 | N6: =INDIRECT(ADDRESS(K7,6,3,,"ΣΤΟΙΧΕΙΑ")) -> 41183 | O6: =INDIRECT(ADDRESS(L7,6,3,,"ΣΤΟΙΧΕΙΑ")) -> 41214 | P6: =INDIRECT(ADDRESS(M7,6,3,,"ΣΤΟΙΧΕΙΑ")) -> 41244 | Q6: =INDIRECT(ADDRESS(N7,6,3,,"ΣΤΟΙΧΕΙΑ")) -> 41275 | ... S6: =INDIRECT(ADDRESS(P7,6,3,,"ΣΤΟΙΧΕΙΑ")) -> 41334 | T6: Ποσό
A7: 1 | B7: =A7+1 -> 2 | C7: =B7+1 -> 3 | F7: =C7+1 -> 4 | G7: =F7+4 -> 8 | H7: =G7+1 -> 9 | I7: =H7+1 -> 10 | J7: =I7+1 -> 11 | K7: =J7+1 -> 12 | L7: =K7+1 -> 13 | M7: =L7+1 -> 14 | N7: =M7+1 -> 15 | O7: =N7+1 -> 16 | ... S7: =R7+1 -> 20 | T7: =F7+1 -> 5
A8: =IF(B8="","",1) -> 1 | B8: =IF(Διαμερίσματα!B6="","",Διαμερίσματα!B6) -> Κ1 | C8: =IF(Διαμερίσματα!I6="","",Διαμερίσματα!I6) -> Ιδιοκτήτης-1 | F8: =IFERROR(HLOOKUP(ΣΤΟΙΧΕΙΑ!$C$11,Ώρες!$D$29:$R$52,2+A8,FALSE),0) -> 0 | G8: =IF(ΣΤΟΙΧΕΙΑ!D41=0,"",ΣΤΟΙΧΕΙΑ!D41) | H8: =IF(ΣΤΟΙΧΕΙΑ!E41=0,"",ΣΤΟΙΧΕΙΑ!E41) -> 44.314208 | I8: =IF(ΣΤΟΙΧΕΙΑ!F41=0,"",ΣΤΟΙΧΕΙΑ!F41) | J8: =IF(ΣΤΟΙΧΕΙΑ!G41=0,"",ΣΤΟΙΧΕΙΑ!G41) | K8: =IF(ΣΤΟΙΧΕΙΑ!H41=0,"",ΣΤΟΙΧΕΙΑ!H41) | L8: =IF(ΣΤΟΙΧΕΙΑ!I41=0,"",ΣΤΟΙΧΕΙΑ!I41) | M8: =IF(ΣΤΟΙΧΕΙΑ!J41=0,"",ΣΤΟΙΧΕΙΑ!J41) | N8: =IF(ΣΤΟΙΧΕΙΑ!K41=0,"",ΣΤΟΙΧΕΙΑ!K41) | ... S8: =IF(ΣΤΟΙΧΕΙΑ!P41=0,"",ΣΤΟΙΧΕΙΑ!P41) | T8: =IF(SUM(G8:S8)=0,"",SUM(G8:S8)) -> 44.314208
A9: =IF(B9="","",A8+1) -> 2 | B9: =IF(Διαμερίσματα!B7="","",Διαμερίσματα!B7) -> Κ2 | C9: =IF(Διαμερίσματα!I7="","",Διαμερίσματα!I7) -> Ιδιοκτήτης-2 | F9: =IFERROR(HLOOKUP(ΣΤΟΙΧΕΙΑ!$C$11,Ώρες!$D$29:$R$52,2+A9,FALSE),0) -> 0 | G9: =IF(ΣΤΟΙΧΕΙΑ!D42=0,"",ΣΤΟΙΧΕΙΑ!D42) | H9: =IF(ΣΤΟΙΧΕΙΑ!E42=0,"",ΣΤΟΙΧΕΙΑ!E42) -> 49.190348 | I9: =IF(ΣΤΟΙΧΕΙΑ!F42=0,"",ΣΤΟΙΧΕΙΑ!F42) | J9: =IF(ΣΤΟΙΧΕΙΑ!G42=0,"",ΣΤΟΙΧΕΙΑ!G42) | K9: =IF(ΣΤΟΙΧΕΙΑ!H42=0,"",ΣΤΟΙΧΕΙΑ!H42) | L9: =IF(ΣΤΟΙΧΕΙΑ!I42=0,"",ΣΤΟΙΧΕΙΑ!I42) | M9: =IF(ΣΤΟΙΧΕΙΑ!J42=0,"",ΣΤΟΙΧΕΙΑ!J42) | N9: =IF(ΣΤΟΙΧΕΙΑ!K42=0,"",ΣΤΟΙΧΕΙΑ!K42) | ... S9: =IF(ΣΤΟΙΧΕΙΑ!P42=0,"",ΣΤΟΙΧΕΙΑ!P42) | T9: =IF(SUM(G9:S9)=0,"",SUM(G9:S9)) -> 49.190348
A10: =IF(B10="","",A9+1) -> 3 | B10: =IF(Διαμερίσματα!B8="","",Διαμερίσματα!B8) -> Κ3 | C10: =IF(Διαμερίσματα!I8="","",Διαμερίσματα!I8) -> Ιδιοκτήτης-3 | F10: =IFERROR(HLOOKUP(ΣΤΟΙΧΕΙΑ!$C$11,Ώρες!$D$29:$R$52,2+A10,FALSE),0) -> 99 | G10: =IF(ΣΤΟΙΧΕΙΑ!D43=0,"",ΣΤΟΙΧΕΙΑ!D43) | H10: =IF(ΣΤΟΙΧΕΙΑ!E43=0,"",ΣΤΟΙΧΕΙΑ!E43) -> 225.03995 | I10: =IF(ΣΤΟΙΧΕΙΑ!F43=0,"",ΣΤΟΙΧΕΙΑ!F43) | J10: =IF(ΣΤΟΙΧΕΙΑ!G43=0,"",ΣΤΟΙΧΕΙΑ!G43) | K10: =IF(ΣΤΟΙΧΕΙΑ!H43=0,"",ΣΤΟΙΧΕΙΑ!H43) | L10: =IF(ΣΤΟΙΧΕΙΑ!I43=0,"",ΣΤΟΙΧΕΙΑ!I43) | M10: =IF(ΣΤΟΙΧΕΙΑ!J43=0,"",ΣΤΟΙΧΕΙΑ!J43) | N10: =IF(ΣΤΟΙΧΕΙΑ!K43=0,"",ΣΤΟΙΧΕΙΑ!K43) | ... S10: =IF(ΣΤΟΙΧΕΙΑ!P43=0,"",ΣΤΟΙΧΕΙΑ!P43) | T10: =IF(SUM(G10:S10)=0,"",SUM(G10:S10)) -> 225.03995
A11: =IF(B11="","",A10+1) -> 4 | B11: =IF(Διαμερίσματα!B9="","",Διαμερίσματα!B9) -> Α1 | C11: =IF(Διαμερίσματα!I9="","",Διαμερίσματα!I9) -> Ιδιοκτήτης-4 | F11: =IFERROR(HLOOKUP(ΣΤΟΙΧΕΙΑ!$C$11,Ώρες!$D$29:$R$52,2+A11,FALSE),0) -> 56 | G11: =IF(ΣΤΟΙΧΕΙΑ!D44=0,"",ΣΤΟΙΧΕΙΑ!D44) | H11: =IF(ΣΤΟΙΧΕΙΑ!E44=0,"",ΣΤΟΙΧΕΙΑ!E44) -> 178.03119 | I11: =IF(ΣΤΟΙΧΕΙΑ!F44=0,"",ΣΤΟΙΧΕΙΑ!F44) | J11: =IF(ΣΤΟΙΧΕΙΑ!G44=0,"",ΣΤΟΙΧΕΙΑ!G44) | K11: =IF(ΣΤΟΙΧΕΙΑ!H44=0,"",ΣΤΟΙΧΕΙΑ!H44) | L11: =IF(ΣΤΟΙΧΕΙΑ!I44=0,"",ΣΤΟΙΧΕΙΑ!I44) | M11: =IF(ΣΤΟΙΧΕΙΑ!J44=0,"",ΣΤΟΙΧΕΙΑ!J44) | N11: =IF(ΣΤΟΙΧΕΙΑ!K44=0,"",ΣΤΟΙΧΕΙΑ!K44) | ... S11: =IF(ΣΤΟΙΧΕΙΑ!P44=0,"",ΣΤΟΙΧΕΙΑ!P44) | T11: =IF(SUM(G11:S11)=0,"",SUM(G11:S11)) -> 178.03119
A12: =IF(B12="","",A11+1) -> 5 | B12: =IF(Διαμερίσματα!B10="","",Διαμερίσματα!B10) -> Α2 | C12: =IF(Διαμερίσματα!I10="","",Διαμερίσματα!I10) -> Ιδιοκτήτης-5 | F12: =IFERROR(HLOOKUP(ΣΤΟΙΧΕΙΑ!$C$11,Ώρες!$D$29:$R$52,2+A12,FALSE),0) -> 67 | G12: =IF(ΣΤΟΙΧΕΙΑ!D45=0,"",ΣΤΟΙΧΕΙΑ!D45) | H12: =IF(ΣΤΟΙΧΕΙΑ!E45=0,"",ΣΤΟΙΧΕΙΑ!E45) -> 164.47441 | I12: =IF(ΣΤΟΙΧΕΙΑ!F45=0,"",ΣΤΟΙΧΕΙΑ!F45) | J12: =IF(ΣΤΟΙΧΕΙΑ!G45=0,"",ΣΤΟΙΧΕΙΑ!G45) | K12: =IF(ΣΤΟΙΧΕΙΑ!H45=0,"",ΣΤΟΙΧΕΙΑ!H45) | L12: =IF(ΣΤΟΙΧΕΙΑ!I45=0,"",ΣΤΟΙΧΕΙΑ!I45) | M12: =IF(ΣΤΟΙΧΕΙΑ!J45=0,"",ΣΤΟΙΧΕΙΑ!J45) | N12: =IF(ΣΤΟΙΧΕΙΑ!K45=0,"",ΣΤΟΙΧΕΙΑ!K45) | ... S12: =IF(ΣΤΟΙΧΕΙΑ!P45=0,"",ΣΤΟΙΧΕΙΑ!P45) | T12: =IF(SUM(G12:S12)=0,"",SUM(G12:S12)) -> 164.47441
A13: =IF(B13="","",A12+1) -> 6 | B13: =IF(Διαμερίσματα!B11="","",Διαμερίσματα!B11) -> Α3 | C13: =IF(Διαμερίσματα!I11="","",Διαμερίσματα!I11) -> Ιδιοκτήτης-6 | F13: =IFERROR(HLOOKUP(ΣΤΟΙΧΕΙΑ!$C$11,Ώρες!$D$29:$R$52,2+A13,FALSE),0) -> 0 | G13: =IF(ΣΤΟΙΧΕΙΑ!D46=0,"",ΣΤΟΙΧΕΙΑ!D46) | H13: =IF(ΣΤΟΙΧΕΙΑ!E46=0,"",ΣΤΟΙΧΕΙΑ!E46) -> 29.674312 | I13: =IF(ΣΤΟΙΧΕΙΑ!F46=0,"",ΣΤΟΙΧΕΙΑ!F46) | J13: =IF(ΣΤΟΙΧΕΙΑ!G46=0,"",ΣΤΟΙΧΕΙΑ!G46) | K13: =IF(ΣΤΟΙΧΕΙΑ!H46=0,"",ΣΤΟΙΧΕΙΑ!H46) | L13: =IF(ΣΤΟΙΧΕΙΑ!I46=0,"",ΣΤΟΙΧΕΙΑ!I46) | M13: =IF(ΣΤΟΙΧΕΙΑ!J46=0,"",ΣΤΟΙΧΕΙΑ!J46) | N13: =IF(ΣΤΟΙΧΕΙΑ!K46=0,"",ΣΤΟΙΧΕΙΑ!K46) | ... S13: =IF(ΣΤΟΙΧΕΙΑ!P46=0,"",ΣΤΟΙΧΕΙΑ!P46) | T13: =IF(SUM(G13:S13)=0,"",SUM(G13:S13)) -> 29.674312
A14: =IF(B14="","",A13+1) -> 7 | B14: =IF(Διαμερίσματα!B12="","",Διαμερίσματα!B12) -> Α4 | C14: =IF(Διαμερίσματα!I12="","",Διαμερίσματα!I12) -> Ιδιοκτήτης-7 | F14: =IFERROR(HLOOKUP(ΣΤΟΙΧΕΙΑ!$C$11,Ώρες!$D$29:$R$52,2+A14,FALSE),0) -> 0 | G14: =IF(ΣΤΟΙΧΕΙΑ!D47=0,"",ΣΤΟΙΧΕΙΑ!D47) | H14: =IF(ΣΤΟΙΧΕΙΑ!E47=0,"",ΣΤΟΙΧΕΙΑ!E47) -> 78.11043 | I14: =IF(ΣΤΟΙΧΕΙΑ!F47=0,"",ΣΤΟΙΧΕΙΑ!F47) | J14: =IF(ΣΤΟΙΧΕΙΑ!G47=0,"",ΣΤΟΙΧΕΙΑ!G47) | K14: =IF(ΣΤΟΙΧΕΙΑ!H47=0,"",ΣΤΟΙΧΕΙΑ!H47) | L14: =IF(ΣΤΟΙΧΕΙΑ!I47=0,"",ΣΤΟΙΧΕΙΑ!I47) | M14: =IF(ΣΤΟΙΧΕΙΑ!J47=0,"",ΣΤΟΙΧΕΙΑ!J47) | N14: =IF(ΣΤΟΙΧΕΙΑ!K47=0,"",ΣΤΟΙΧΕΙΑ!K47) | ... S14: =IF(ΣΤΟΙΧΕΙΑ!P47=0,"",ΣΤΟΙΧΕΙΑ!P47) | T14: =IF(SUM(G14:S14)=0,"",SUM(G14:S14)) -> 78.11043
A15: =IF(B15="","",A14+1) -> 8 | B15: =IF(Διαμερίσματα!B13="","",Διαμερίσματα!B13) -> Β1 | C15: =IF(Διαμερίσματα!I13="","",Διαμερίσματα!I13) -> Ιδιοκτήτης-8 | F15: =IFERROR(HLOOKUP(ΣΤΟΙΧΕΙΑ!$C$11,Ώρες!$D$29:$R$52,2+A15,FALSE),0) -> 21 | G15: =IF(ΣΤΟΙΧΕΙΑ!D48=0,"",ΣΤΟΙΧΕΙΑ!D48) | H15: =IF(ΣΤΟΙΧΕΙΑ!E48=0,"",ΣΤΟΙΧΕΙΑ!E48) -> 77.398602 | I15: =IF(ΣΤΟΙΧΕΙΑ!F48=0,"",ΣΤΟΙΧΕΙΑ!F48) | J15: =IF(ΣΤΟΙΧΕΙΑ!G48=0,"",ΣΤΟΙΧΕΙΑ!G48) | K15: =IF(ΣΤΟΙΧΕΙΑ!H48=0,"",ΣΤΟΙΧΕΙΑ!H48) | L15: =IF(ΣΤΟΙΧΕΙΑ!I48=0,"",ΣΤΟΙΧΕΙΑ!I48) | M15: =IF(ΣΤΟΙΧΕΙΑ!J48=0,"",ΣΤΟΙΧΕΙΑ!J48) | N15: =IF(ΣΤΟΙΧΕΙΑ!K48=0,"",ΣΤΟΙΧΕΙΑ!K48) | ... S15: =IF(ΣΤΟΙΧΕΙΑ!P48=0,"",ΣΤΟΙΧΕΙΑ!P48) | T15: =IF(SUM(G15:S15)=0,"",SUM(G15:S15)) -> 77.398602
A16: =IF(B16="","",A15+1) -> 9 | B16: =IF(Διαμερίσματα!B14="","",Διαμερίσματα!B14) -> Β2 | C16: =IF(Διαμερίσματα!I14="","",Διαμερίσματα!I14) -> Ιδιοκτήτης-9 | F16: =IFERROR(HLOOKUP(ΣΤΟΙΧΕΙΑ!$C$11,Ώρες!$D$29:$R$52,2+A16,FALSE),0) -> 12 | G16: =IF(ΣΤΟΙΧΕΙΑ!D49=0,"",ΣΤΟΙΧΕΙΑ!D49) | H16: =IF(ΣΤΟΙΧΕΙΑ!E49=0,"",ΣΤΟΙΧΕΙΑ!E49) -> 133.28129 | I16: =IF(ΣΤΟΙΧΕΙΑ!F49=0,"",ΣΤΟΙΧΕΙΑ!F49) | J16: =IF(ΣΤΟΙΧΕΙΑ!G49=0,"",ΣΤΟΙΧΕΙΑ!G49) | K16: =IF(ΣΤΟΙΧΕΙΑ!H49=0,"",ΣΤΟΙΧΕΙΑ!H49) | L16: =IF(ΣΤΟΙΧΕΙΑ!I49=0,"",ΣΤΟΙΧΕΙΑ!I49) | M16: =IF(ΣΤΟΙΧΕΙΑ!J49=0,"",ΣΤΟΙΧΕΙΑ!J49) | N16: =IF(ΣΤΟΙΧΕΙΑ!K49=0,"",ΣΤΟΙΧΕΙΑ!K49) | ... S16: =IF(ΣΤΟΙΧΕΙΑ!P49=0,"",ΣΤΟΙΧΕΙΑ!P49) | T16: =IF(SUM(G16:S16)=0,"",SUM(G16:S16)) -> 133.28129
A17: =IF(B17="","",A16+1) -> 10 | B17: =IF(Διαμερίσματα!B15="","",Διαμερίσματα!B15) -> Β3 | C17: =IF(Διαμερίσματα!I15="","",Διαμερίσματα!I15) -> Ιδιοκτήτης-10 | F17: =IFERROR(HLOOKUP(ΣΤΟΙΧΕΙΑ!$C$11,Ώρες!$D$29:$R$52,2+A17,FALSE),0) -> 60 | G17: =IF(ΣΤΟΙΧΕΙΑ!D50=0,"",ΣΤΟΙΧΕΙΑ!D50) | H17: =IF(ΣΤΟΙΧΕΙΑ!E50=0,"",ΣΤΟΙΧΕΙΑ!E50) -> 236.65566 | I17: =IF(ΣΤΟΙΧΕΙΑ!F50=0,"",ΣΤΟΙΧΕΙΑ!F50) | J17: =IF(ΣΤΟΙΧΕΙΑ!G50=0,"",ΣΤΟΙΧΕΙΑ!G50) | K17: =IF(ΣΤΟΙΧΕΙΑ!H50=0,"",ΣΤΟΙΧΕΙΑ!H50) | L17: =IF(ΣΤΟΙΧΕΙΑ!I50=0,"",ΣΤΟΙΧΕΙΑ!I50) | M17: =IF(ΣΤΟΙΧΕΙΑ!J50=0,"",ΣΤΟΙΧΕΙΑ!J50) | N17: =IF(ΣΤΟΙΧΕΙΑ!K50=0,"",ΣΤΟΙΧΕΙΑ!K50) | ... S17: =IF(ΣΤΟΙΧΕΙΑ!P50=0,"",ΣΤΟΙΧΕΙΑ!P50) | T17: =IF(SUM(G17:S17)=0,"",SUM(G17:S17)) -> 236.65566
A18: =IF(B18="","",A17+1) -> 11 | B18: =IF(Διαμερίσματα!B16="","",Διαμερίσματα!B16) -> Β4 | C18: =IF(Διαμερίσματα!I16="","",Διαμερίσματα!I16) -> Ιδιοκτήτης-11 | F18: =IFERROR(HLOOKUP(ΣΤΟΙΧΕΙΑ!$C$11,Ώρες!$D$29:$R$52,2+A18,FALSE),0) -> 72 | G18: =IF(ΣΤΟΙΧΕΙΑ!D51=0,"",ΣΤΟΙΧΕΙΑ!D51) | H18: =IF(ΣΤΟΙΧΕΙΑ!E51=0,"",ΣΤΟΙΧΕΙΑ!E51) | I18: =IF(ΣΤΟΙΧΕΙΑ!F51=0,"",ΣΤΟΙΧΕΙΑ!F51) | J18: =IF(ΣΤΟΙΧΕΙΑ!G51=0,"",ΣΤΟΙΧΕΙΑ!G51) | K18: =IF(ΣΤΟΙΧΕΙΑ!H51=0,"",ΣΤΟΙΧΕΙΑ!H51) | L18: =IF(ΣΤΟΙΧΕΙΑ!I51=0,"",ΣΤΟΙΧΕΙΑ!I51) | M18: =IF(ΣΤΟΙΧΕΙΑ!J51=0,"",ΣΤΟΙΧΕΙΑ!J51) | N18: =IF(ΣΤΟΙΧΕΙΑ!K51=0,"",ΣΤΟΙΧΕΙΑ!K51) | ... S18: =IF(ΣΤΟΙΧΕΙΑ!P51=0,"",ΣΤΟΙΧΕΙΑ!P51) | T18: =IF(SUM(G18:S18)=0,"",SUM(G18:S18))
A19: =IF(B19="","",A18+1) -> 12 | B19: =IF(Διαμερίσματα!B17="","",Διαμερίσματα!B17) -> Γ1 | C19: =IF(Διαμερίσματα!I17="","",Διαμερίσματα!I17) -> Ιδιοκτήτης-12 | F19: =IFERROR(HLOOKUP(ΣΤΟΙΧΕΙΑ!$C$11,Ώρες!$D$29:$R$52,2+A19,FALSE),0) -> 0 | G19: =IF(ΣΤΟΙΧΕΙΑ!D62=0,"",ΣΤΟΙΧΕΙΑ!D62) | H19: =IF(ΣΤΟΙΧΕΙΑ!E52=0,"",ΣΤΟΙΧΕΙΑ!E52) -> 26.341334 | I19: =IF(ΣΤΟΙΧΕΙΑ!F52=0,"",ΣΤΟΙΧΕΙΑ!F52) | J19: =IF(ΣΤΟΙΧΕΙΑ!G52=0,"",ΣΤΟΙΧΕΙΑ!G52) | K19: =IF(ΣΤΟΙΧΕΙΑ!H52=0,"",ΣΤΟΙΧΕΙΑ!H52) | L19: =IF(ΣΤΟΙΧΕΙΑ!I52=0,"",ΣΤΟΙΧΕΙΑ!I52) | M19: =IF(ΣΤΟΙΧΕΙΑ!J52=0,"",ΣΤΟΙΧΕΙΑ!J52) | N19: =IF(ΣΤΟΙΧΕΙΑ!K52=0,"",ΣΤΟΙΧΕΙΑ!K52) | O19: =IF(ΣΤΟΙΧΕΙΑ!L52=0,"",ΣΤΟΙΧΕΙΑ!L52) | ... S19: =IF(ΣΤΟΙΧΕΙΑ!P52=0,"",ΣΤΟΙΧΕΙΑ!P52) | T19: =IF(SUM(G19:S19)=0,"",SUM(G19:S19)) -> 26.341334
A20: =IF(B20="","",A19+1) -> 13 | B20: =IF(Διαμερίσματα!B18="","",Διαμερίσματα!B18) -> Γ2 | C20: =IF(Διαμερίσματα!I18="","",Διαμερίσματα!I18) -> Ιδιοκτήτης-13 | F20: =IFERROR(HLOOKUP(ΣΤΟΙΧΕΙΑ!$C$11,Ώρες!$D$29:$R$52,2+A20,FALSE),0) -> 0 | G20: =IF(ΣΤΟΙΧΕΙΑ!D63=0,"",ΣΤΟΙΧΕΙΑ!D63) | H20: =IF(ΣΤΟΙΧΕΙΑ!E53=0,"",ΣΤΟΙΧΕΙΑ!E53) -> 26.371227 | I20: =IF(ΣΤΟΙΧΕΙΑ!F53=0,"",ΣΤΟΙΧΕΙΑ!F53) | J20: =IF(ΣΤΟΙΧΕΙΑ!G53=0,"",ΣΤΟΙΧΕΙΑ!G53) | K20: =IF(ΣΤΟΙΧΕΙΑ!H53=0,"",ΣΤΟΙΧΕΙΑ!H53) | L20: =IF(ΣΤΟΙΧΕΙΑ!I53=0,"",ΣΤΟΙΧΕΙΑ!I53) | M20: =IF(ΣΤΟΙΧΕΙΑ!J53=0,"",ΣΤΟΙΧΕΙΑ!J53) | N20: =IF(ΣΤΟΙΧΕΙΑ!K53=0,"",ΣΤΟΙΧΕΙΑ!K53) | O20: =IF(ΣΤΟΙΧΕΙΑ!L53=0,"",ΣΤΟΙΧΕΙΑ!L53) | ... S20: =IF(ΣΤΟΙΧΕΙΑ!P53=0,"",ΣΤΟΙΧΕΙΑ!P53) | T20: =IF(SUM(G20:S20)=0,"",SUM(G20:S20)) -> 26.371227
A21: =IF(B21="","",A20+1) -> 14 | B21: =IF(Διαμερίσματα!B19="","",Διαμερίσματα!B19) -> Γ3 | C21: =IF(Διαμερίσματα!I19="","",Διαμερίσματα!I19) -> Ιδιοκτήτης-14 | F21: =IFERROR(HLOOKUP(ΣΤΟΙΧΕΙΑ!$C$11,Ώρες!$D$29:$R$52,2+A21,FALSE),0) -> 0 | G21: =IF(ΣΤΟΙΧΕΙΑ!D64=0,"",ΣΤΟΙΧΕΙΑ!D64) | H21: =IF(ΣΤΟΙΧΕΙΑ!E54=0,"",ΣΤΟΙΧΕΙΑ!E54) -> 26.371227 | I21: =IF(ΣΤΟΙΧΕΙΑ!F54=0,"",ΣΤΟΙΧΕΙΑ!F54) | J21: =IF(ΣΤΟΙΧΕΙΑ!G54=0,"",ΣΤΟΙΧΕΙΑ!G54) | K21: =IF(ΣΤΟΙΧΕΙΑ!H54=0,"",ΣΤΟΙΧΕΙΑ!H54) | L21: =IF(ΣΤΟΙΧΕΙΑ!I54=0,"",ΣΤΟΙΧΕΙΑ!I54) | M21: =IF(ΣΤΟΙΧΕΙΑ!J54=0,"",ΣΤΟΙΧΕΙΑ!J54) | N21: =IF(ΣΤΟΙΧΕΙΑ!K54=0,"",ΣΤΟΙΧΕΙΑ!K54) | O21: =IF(ΣΤΟΙΧΕΙΑ!L54=0,"",ΣΤΟΙΧΕΙΑ!L54) | ... S21: =IF(ΣΤΟΙΧΕΙΑ!P54=0,"",ΣΤΟΙΧΕΙΑ!P54) | T21: =IF(SUM(G21:S21)=0,"",SUM(G21:S21)) -> 26.371227
A22: =IF(B22="","",A21+1) -> 15 | B22: =IF(Διαμερίσματα!B20="","",Διαμερίσματα!B20) -> Γ4 | C22: =IF(Διαμερίσματα!I20="","",Διαμερίσματα!I20) -> Ιδιοκτήτης-15 | F22: =IFERROR(HLOOKUP(ΣΤΟΙΧΕΙΑ!$C$11,Ώρες!$D$29:$R$52,2+A22,FALSE),0) -> 0 | G22: =IF(ΣΤΟΙΧΕΙΑ!D65=0,"",ΣΤΟΙΧΕΙΑ!D65) | H22: =IF(ΣΤΟΙΧΕΙΑ!E55=0,"",ΣΤΟΙΧΕΙΑ!E55) -> 26.371227 | I22: =IF(ΣΤΟΙΧΕΙΑ!F55=0,"",ΣΤΟΙΧΕΙΑ!F55) | J22: =IF(ΣΤΟΙΧΕΙΑ!G55=0,"",ΣΤΟΙΧΕΙΑ!G55) | K22: =IF(ΣΤΟΙΧΕΙΑ!H55=0,"",ΣΤΟΙΧΕΙΑ!H55) | L22: =IF(ΣΤΟΙΧΕΙΑ!I55=0,"",ΣΤΟΙΧΕΙΑ!I55) | M22: =IF(ΣΤΟΙΧΕΙΑ!J55=0,"",ΣΤΟΙΧΕΙΑ!J55) | N22: =IF(ΣΤΟΙΧΕΙΑ!K55=0,"",ΣΤΟΙΧΕΙΑ!K55) | O22: =IF(ΣΤΟΙΧΕΙΑ!L55=0,"",ΣΤΟΙΧΕΙΑ!L55) | ... S22: =IF(ΣΤΟΙΧΕΙΑ!P55=0,"",ΣΤΟΙΧΕΙΑ!P55) | T22: =IF(SUM(G22:S22)=0,"",SUM(G22:S22)) -> 26.371227
A23: =IF(B23="","",A22+1) -> 16 | B23: =IF(Διαμερίσματα!B21="","",Διαμερίσματα!B21) -> Δ1 | C23: =IF(Διαμερίσματα!I21="","",Διαμερίσματα!I21) -> Ιδιοκτήτης-16 | F23: =IFERROR(HLOOKUP(ΣΤΟΙΧΕΙΑ!$C$11,Ώρες!$D$29:$R$52,2+A23,FALSE),0) -> 0 | G23: =IF(ΣΤΟΙΧΕΙΑ!D66=0,"",ΣΤΟΙΧΕΙΑ!D66) | H23: =IF(ΣΤΟΙΧΕΙΑ!E56=0,"",ΣΤΟΙΧΕΙΑ!E56) -> 26.371227 | I23: =IF(ΣΤΟΙΧΕΙΑ!F56=0,"",ΣΤΟΙΧΕΙΑ!F56) | J23: =IF(ΣΤΟΙΧΕΙΑ!G56=0,"",ΣΤΟΙΧΕΙΑ!G56) | K23: =IF(ΣΤΟΙΧΕΙΑ!H56=0,"",ΣΤΟΙΧΕΙΑ!H56) | L23: =IF(ΣΤΟΙΧΕΙΑ!I56=0,"",ΣΤΟΙΧΕΙΑ!I56) | M23: =IF(ΣΤΟΙΧΕΙΑ!J56=0,"",ΣΤΟΙΧΕΙΑ!J56) | N23: =IF(ΣΤΟΙΧΕΙΑ!K56=0,"",ΣΤΟΙΧΕΙΑ!K56) | O23: =IF(ΣΤΟΙΧΕΙΑ!L56=0,"",ΣΤΟΙΧΕΙΑ!L56) | ... S23: =IF(ΣΤΟΙΧΕΙΑ!P56=0,"",ΣΤΟΙΧΕΙΑ!P56) | T23: =IF(SUM(G23:S23)=0,"",SUM(G23:S23)) -> 26.371227
A24: =IF(B24="","",A23+1) -> 17 | B24: =IF(Διαμερίσματα!B22="","",Διαμερίσματα!B22) -> Δ2 | C24: =IF(Διαμερίσματα!I22="","",Διαμερίσματα!I22) -> Ιδιοκτήτης-17 | F24: =IFERROR(HLOOKUP(ΣΤΟΙΧΕΙΑ!$C$11,Ώρες!$D$29:$R$52,2+A24,FALSE),0) -> 0 | G24: =IF(ΣΤΟΙΧΕΙΑ!D67=0,"",ΣΤΟΙΧΕΙΑ!D67) | H24: =IF(ΣΤΟΙΧΕΙΑ!E57=0,"",ΣΤΟΙΧΕΙΑ!E57) -> 26.371227 | I24: =IF(ΣΤΟΙΧΕΙΑ!F57=0,"",ΣΤΟΙΧΕΙΑ!F57) | J24: =IF(ΣΤΟΙΧΕΙΑ!G57=0,"",ΣΤΟΙΧΕΙΑ!G57) | K24: =IF(ΣΤΟΙΧΕΙΑ!H57=0,"",ΣΤΟΙΧΕΙΑ!H57) | L24: =IF(ΣΤΟΙΧΕΙΑ!I57=0,"",ΣΤΟΙΧΕΙΑ!I57) | M24: =IF(ΣΤΟΙΧΕΙΑ!J57=0,"",ΣΤΟΙΧΕΙΑ!J57) | N24: =IF(ΣΤΟΙΧΕΙΑ!K57=0,"",ΣΤΟΙΧΕΙΑ!K57) | O24: =IF(ΣΤΟΙΧΕΙΑ!L57=0,"",ΣΤΟΙΧΕΙΑ!L57) | ... S24: =IF(ΣΤΟΙΧΕΙΑ!P57=0,"",ΣΤΟΙΧΕΙΑ!P57) | T24: =IF(SUM(G24:S24)=0,"",SUM(G24:S24)) -> 26.371227
A25: =IF(B25="","",A24+1) -> 18 | B25: =IF(Διαμερίσματα!B23="","",Διαμερίσματα!B23) -> Δ3 | C25: =IF(Διαμερίσματα!I23="","",Διαμερίσματα!I23) -> Ιδιοκτήτης-18 | F25: =IFERROR(HLOOKUP(ΣΤΟΙΧΕΙΑ!$C$11,Ώρες!$D$29:$R$52,2+A25,FALSE),0) -> 0 | G25: =IF(ΣΤΟΙΧΕΙΑ!D68=0,"",ΣΤΟΙΧΕΙΑ!D68) | H25: =IF(ΣΤΟΙΧΕΙΑ!E58=0,"",ΣΤΟΙΧΕΙΑ!E58) -> 26.518445 | I25: =IF(ΣΤΟΙΧΕΙΑ!F58=0,"",ΣΤΟΙΧΕΙΑ!F58) | J25: =IF(ΣΤΟΙΧΕΙΑ!G58=0,"",ΣΤΟΙΧΕΙΑ!G58) | K25: =IF(ΣΤΟΙΧΕΙΑ!H58=0,"",ΣΤΟΙΧΕΙΑ!H58) | L25: =IF(ΣΤΟΙΧΕΙΑ!I58=0,"",ΣΤΟΙΧΕΙΑ!I58) | M25: =IF(ΣΤΟΙΧΕΙΑ!J58=0,"",ΣΤΟΙΧΕΙΑ!J58) | N25: =IF(ΣΤΟΙΧΕΙΑ!K58=0,"",ΣΤΟΙΧΕΙΑ!K58) | O25: =IF(ΣΤΟΙΧΕΙΑ!L58=0,"",ΣΤΟΙΧΕΙΑ!L58) | ... S25: =IF(ΣΤΟΙΧΕΙΑ!P58=0,"",ΣΤΟΙΧΕΙΑ!P58) | T25: =IF(SUM(G25:S25)=0,"",SUM(G25:S25)) -> 26.518445
A26: =IF(B26="","",A25+1) -> 19 | B26: =IF(Διαμερίσματα!B24="","",Διαμερίσματα!B24) -> Δ4 | C26: =IF(Διαμερίσματα!I24="","",Διαμερίσματα!I24) -> Ιδιοκτήτης-19 | F26: =IFERROR(HLOOKUP(ΣΤΟΙΧΕΙΑ!$C$11,Ώρες!$D$29:$R$52,2+A26,FALSE),0) -> 0 | G26: =IF(ΣΤΟΙΧΕΙΑ!D69=0,"",ΣΤΟΙΧΕΙΑ!D69) | H26: =IF(ΣΤΟΙΧΕΙΑ!E59=0,"",ΣΤΟΙΧΕΙΑ!E59) -> 26.371227 | I26: =IF(ΣΤΟΙΧΕΙΑ!F59=0,"",ΣΤΟΙΧΕΙΑ!F59) | J26: =IF(ΣΤΟΙΧΕΙΑ!G59=0,"",ΣΤΟΙΧΕΙΑ!G59) | K26: =IF(ΣΤΟΙΧΕΙΑ!H59=0,"",ΣΤΟΙΧΕΙΑ!H59) | L26: =IF(ΣΤΟΙΧΕΙΑ!I59=0,"",ΣΤΟΙΧΕΙΑ!I59) | M26: =IF(ΣΤΟΙΧΕΙΑ!J59=0,"",ΣΤΟΙΧΕΙΑ!J59) | N26: =IF(ΣΤΟΙΧΕΙΑ!K59=0,"",ΣΤΟΙΧΕΙΑ!K59) | O26: =IF(ΣΤΟΙΧΕΙΑ!L59=0,"",ΣΤΟΙΧΕΙΑ!L59) | ... S26: =IF(ΣΤΟΙΧΕΙΑ!P59=0,"",ΣΤΟΙΧΕΙΑ!P59) | T26: =IF(SUM(G26:S26)=0,"",SUM(G26:S26)) -> 26.371227
A27: =IF(B27="","",A26+1) -> 20 | B27: =IF(Διαμερίσματα!B25="","",Διαμερίσματα!B25) -> Ε1 | C27: =IF(Διαμερίσματα!I25="","",Διαμερίσματα!I25) -> Ιδιοκτήτης-20 | F27: =IFERROR(HLOOKUP(ΣΤΟΙΧΕΙΑ!$C$11,Ώρες!$D$29:$R$52,2+A27,FALSE),0) -> 0 | G27: =IF(ΣΤΟΙΧΕΙΑ!D70=0,"",ΣΤΟΙΧΕΙΑ!D70) | H27: =IF(ΣΤΟΙΧΕΙΑ!E60=0,"",ΣΤΟΙΧΕΙΑ!E60) -> 26.371227 | I27: =IF(ΣΤΟΙΧΕΙΑ!F60=0,"",ΣΤΟΙΧΕΙΑ!F60) | J27: =IF(ΣΤΟΙΧΕΙΑ!G60=0,"",ΣΤΟΙΧΕΙΑ!G60) | K27: =IF(ΣΤΟΙΧΕΙΑ!H60=0,"",ΣΤΟΙΧΕΙΑ!H60) | L27: =IF(ΣΤΟΙΧΕΙΑ!I60=0,"",ΣΤΟΙΧΕΙΑ!I60) | M27: =IF(ΣΤΟΙΧΕΙΑ!J60=0,"",ΣΤΟΙΧΕΙΑ!J60) | N27: =IF(ΣΤΟΙΧΕΙΑ!K60=0,"",ΣΤΟΙΧΕΙΑ!K60) | O27: =IF(ΣΤΟΙΧΕΙΑ!L60=0,"",ΣΤΟΙΧΕΙΑ!L60) | ... S27: =IF(ΣΤΟΙΧΕΙΑ!P60=0,"",ΣΤΟΙΧΕΙΑ!P60) | T27: =IF(SUM(G27:S27)=0,"",SUM(G27:S27)) -> 26.371227
A28: =IF(B28="","",A27+1) -> 21 | B28: =IF(Διαμερίσματα!B26="","",Διαμερίσματα!B26) -> Ε2 | C28: =IF(Διαμερίσματα!I26="","",Διαμερίσματα!I26) -> Ιδιοκτήτης-21 | F28: =IFERROR(HLOOKUP(ΣΤΟΙΧΕΙΑ!$C$11,Ώρες!$D$29:$R$52,2+A28,FALSE),0) -> 0 | G28: =IF(ΣΤΟΙΧΕΙΑ!D71=0,"",ΣΤΟΙΧΕΙΑ!D71) | H28: =IF(ΣΤΟΙΧΕΙΑ!E61=0,"",ΣΤΟΙΧΕΙΑ!E61) -> 26.371227 | I28: =IF(ΣΤΟΙΧΕΙΑ!F61=0,"",ΣΤΟΙΧΕΙΑ!F61) | J28: =IF(ΣΤΟΙΧΕΙΑ!G61=0,"",ΣΤΟΙΧΕΙΑ!G61) | K28: =IF(ΣΤΟΙΧΕΙΑ!H61=0,"",ΣΤΟΙΧΕΙΑ!H61) | L28: =IF(ΣΤΟΙΧΕΙΑ!I61=0,"",ΣΤΟΙΧΕΙΑ!I61) | M28: =IF(ΣΤΟΙΧΕΙΑ!J61=0,"",ΣΤΟΙΧΕΙΑ!J61) | N28: =IF(ΣΤΟΙΧΕΙΑ!K61=0,"",ΣΤΟΙΧΕΙΑ!K61) | O28: =IF(ΣΤΟΙΧΕΙΑ!L61=0,"",ΣΤΟΙΧΕΙΑ!L61) | ... S28: =IF(ΣΤΟΙΧΕΙΑ!P61=0,"",ΣΤΟΙΧΕΙΑ!P61) | T28: =IF(SUM(G28:S28)=0,"",SUM(G28:S28)) -> 26.371227
A29: =IF(B29="","",A28+1) -> 22 | B29: =IF(Διαμερίσματα!B27="","",Διαμερίσματα!B27) -> Ε3 | C29: =IF(Διαμερίσματα!I27="","",Διαμερίσματα!I27) -> Ιδιοκτήτης-22 | F29: =IFERROR(HLOOKUP(ΣΤΟΙΧΕΙΑ!$C$11,Ώρες!$D$29:$R$52,2+A29,FALSE),0) -> 0 | G29: =IF(ΣΤΟΙΧΕΙΑ!D72=0,"",ΣΤΟΙΧΕΙΑ!D72) | H29: =IF(ΣΤΟΙΧΕΙΑ!E62=0,"",ΣΤΟΙΧΕΙΑ!E62) | I29: =IF(ΣΤΟΙΧΕΙΑ!F62=0,"",ΣΤΟΙΧΕΙΑ!F62) | J29: =IF(ΣΤΟΙΧΕΙΑ!G62=0,"",ΣΤΟΙΧΕΙΑ!G62) | K29: =IF(ΣΤΟΙΧΕΙΑ!H62=0,"",ΣΤΟΙΧΕΙΑ!H62) | L29: =IF(ΣΤΟΙΧΕΙΑ!I62=0,"",ΣΤΟΙΧΕΙΑ!I62) | M29: =IF(ΣΤΟΙΧΕΙΑ!J62=0,"",ΣΤΟΙΧΕΙΑ!J62) | N29: =IF(ΣΤΟΙΧΕΙΑ!K62=0,"",ΣΤΟΙΧΕΙΑ!K62) | O29: =IF(ΣΤΟΙΧΕΙΑ!L62=0,"",ΣΤΟΙΧΕΙΑ!L62) | ... S29: =IF(ΣΤΟΙΧΕΙΑ!P62=0,"",ΣΤΟΙΧΕΙΑ!P62) | T29: =IF(SUM(G29:S29)=0,"",SUM(G29:S29))
A30: Σ Υ Ν Ο Λ Α (τα Ποσά μπορεί να έχουν απόκλιση μέχρι 1 €, λόγω στρογγυλοποίησης) | F30: =SUM(F8:F29) -> 387 | G30: =IF(ΣΤΟΙΧΕΙΑ!D63=0,"",ΣΤΟΙΧΕΙΑ!D63) | H30: =IF(ΣΤΟΙΧΕΙΑ!E63=0,"",ΣΤΟΙΧΕΙΑ!E63) -> 1480 | I30: =IF(ΣΤΟΙΧΕΙΑ!F63=0,"",ΣΤΟΙΧΕΙΑ!F63) | J30: =IF(ΣΤΟΙΧΕΙΑ!G63=0,"",ΣΤΟΙΧΕΙΑ!G63) | K30: =IF(ΣΤΟΙΧΕΙΑ!H63=0,"",ΣΤΟΙΧΕΙΑ!H63) | L30: =IF(ΣΤΟΙΧΕΙΑ!I63=0,"",ΣΤΟΙΧΕΙΑ!I63) | M30: =IF(ΣΤΟΙΧΕΙΑ!J63=0,"",ΣΤΟΙΧΕΙΑ!J63) | N30: =IF(ΣΤΟΙΧΕΙΑ!K63=0,"",ΣΤΟΙΧΕΙΑ!K63) | ... S30: =IF(ΣΤΟΙΧΕΙΑ!P63=0,"",ΣΤΟΙΧΕΙΑ!P63) | T30: =SUM(T8:T29) -> 1480

Sheet Πετρέλαιο
A1: Δεξαμενή Πετρελαίου | H1: =ΣΤΟΙΧΕΙΑ!C3 -> Κ Ο Ι Ν Ο Χ Ρ Η Σ Τ Α : | X1: Πρόχειρη εκτίμηση Συμβατικού Ύψους, για ορθογώνια Δεξαμενή.
A2: Διαστάσεις σε Μέτρα | D2: Εμβαδόν m2 | E2: Όγκος m3 | F2: Όγκος σε Λίτρα | G2: Λίτρα ανά cm | H2: =ΣΤΟΙΧΕΙΑ!C12 -> Διευθύνση 123 | X2: CM | Y2: Διαφορά CM | Z2: Λίτρα | AA2: Διαφορά Λίτρα | AB2: Συμβατικό Ύψος
A3: Μήκος | B3: Πλάτος | C3: Ύψος | D3: ΜχΠ | E3: ΜχΠχΥ | X3: 5.5 | Y3: =X3-0 -> 5.5 | Z3: 50 | AA3: =Z3-0 -> 50 | AB3: 2.5
A4: 2.5 | B4: 1.25 | C4: 1.25 | D4: =ROUND(A4*B4,3) -> 3.125 | E4: =ROUND(A4*B4*C4,2) -> 3.91 | F4: =E4*1000 -> 3910 | G4: =ROUND(D4*0.01*1000,2) -> 31.25 | X4: 9 | Y4: =X4-X3 -> 3.5 | Z4: 100 | AA4: =Z4-Z3 -> 50 | AB4: 5
A5: =A4 -> 2.5 | B5: =B4 -> 1.25 | C5: =ROUND((E5/D5)*100,1) -> 30.9 | D5: =ROUND(A5*B5,3) -> 3.125 | E5: =ROUND(F5/1000,3) -> 0.966 | F5: 966 | G5: =ROUND(D5*0.01*1000,2) -> 31.25 | H5: Εύρεση Συμβατικού Ύψους | X5: 12 | Y5: =X5-X4 -> 3 | Z5: 150 | AA5: =Z5-Z4 -> 50 | AB5: 7.5
A6: Επιστροφή στην ΠΛΟΗΓΗΣΗ | X6: 14.5 | Y6: =X6-X5 -> 2.5 | Z6: 200 | AA6: =Z6-Z5 -> 50 | AB6: 10
A7: Σύνδεσμοι Υπολογισμών: | C7: http://www.red-bag.com/engintools/hortankvol.php | X7: 17.5 | Y7: =X7-X6 -> 3 | Z7: 250 | AA7: =Z7-Z6 -> 50 | AB7: 12.5
C8: http://users.sch.gr/geoman22/index2.htm | X8: 20 | Y8: =X8-X7 -> 2.5 | Z8: 300 | AA8: =Z8-Z7 -> 50 | AB8: 15
A9: Υπολογισμός Κόστους Πετρελαίου που Κάηκε για την Κατανομή στα Κοινόχρηστα | X9: 22.5 | Y9: =X9-X8 -> 2.5 | Z9: 350 | AA9: =Z9-Z8 -> 50 | AB9: 17.5
A10: Α/Α | B10: Μήνας | C10: Προμήθεια | F10: Ποσότητα (Λίτρα) | I10: Κόστος Αγοράς σε € | N10: Ύψος Δεξαμενής σε cm | Q10: Έλεγχος Παρα-λαβής | R10: Ημερομηνίες Μετρήσεων | S10: Πετρέλαιο που Κάηκε | V10: Κόστος σε € | X10: 24.5 | Y10: =X10-X9 -> 2 | Z10: 400 | AA10: =Z10-Z9 -> 50 | AB10: 20
C11: Ημερομηνία | D11: Προμηθευτής | E11: Απόδειξη Λιαν.Πώλ. | F11: Προηγ. Υπόλοιπο | G11: Αγορά | H11: ΝΕΟ Υπόλοιπο | I11: Προηγ. Υπόλοιπ | J11: ΝΕΟΥ | K11: Συνολ. Υπόλοιπ. | L11: Λίτρου ΝΕΟΥ | M11: ΜΟ/Λ Άκαυστου | N11: Προη- γούμενο | O11: ΝΈΟ | P11: Δια-φορά | S11: Ύψος ΝΈΟ | T11: Μείωση Ύψους | U11: σε Λίτρα | V11: Με ΜΟ Τιμής | X11: 27.3 | Y11: =X11-X10 -> 2.8 | Z11: 450 | AA11: =Z11-Z10 -> 50 | AB11: 22.5
A12: 1 | B12: =A12+1 -> 2 | C12: =B12+1 -> 3 | D12: =C12+1 -> 4 | E12: =D12+1 -> 5 | F12: =E12+1 -> 6 | G12: =F12+1 -> 7 | H12: =G12+1 -> 8 | I12: =H12+1 -> 9 | ... V12: =U12+1 -> 22 | X12: 29.5 | Y12: =X12-X11 -> 2.2 | Z12: 500 | AA12: =Z12-Z11 -> 50 | AB12: 25
A13: 1 | B13: =ΣΤΟΙΧΕΙΑ!F1 -> 40848 | D13: =IF(G13="","",ΣΤΟΙΧΕΙΑ!$C$14) | F13: 110 | H13: =SUM(F13:G13) -> 110 | I13: =ROUND(F13*H4,1) -> 0 | J13: 110 | K13: =I13+J13 -> 110 | L13: =IF(G13="",0,ROUND(J13/G13,3)) -> 0 | M13: =IF(H13=0,0,ROUND(K13/H13,4)) -> 1 | N13: =ROUND(F13/$G$4,1) -> 3.5 | O13: =ROUND(H13/$G$4,1) -> 3.5 | P13: =O13-N13 -> 0 | Q13: =IF(ROUND(P13*$G$4,0)<G13,"ΚΛΕΒΕΙ",ROUND(P13*$G$4,0)) -> 0 | R13: =ΣΤΟΙΧΕΙΑ!F1+27 -> 40875 | S13: 3.5 | T13: =IF(S13="",0,IF(G13="",ROUND(N13-S13,1),ROUND(O13-S13,1))) -> 0 | U13: =ROUND(T13*$G$4,1) -> 0 | V13: =ROUND(U13*M13,0) -> 0 | X13: 32.3 | Y13: =X13-X12 -> 2.8 | Z13: 550 | AA13: =Z13-Z12 -> 50 | AB13: 27.5
A14: =A13+1 -> 2 | B14: =ΣΤΟΙΧΕΙΑ!F2 -> 40878 | D14: =IF(G14="","",ΣΤΟΙΧΕΙΑ!$C$14) -> Βενζινάς | F14: =IF(S13="",H13,ROUND(S13*$G$4,0)) -> 109 | G14: 1200 | H14: =SUM(F14:G14) -> 1309 | I14: =ROUND(F14*M13,1) -> 109 | J14: 981 | K14: =I14+J14 -> 1090 | L14: =IF(G14="",0,ROUND(J14/G14,3)) -> 0.818 | M14: =IF(H14=0,0,ROUND(K14/H14,4)) -> 0.8327 | N14: =ROUND(F14/$G$4,1) -> 3.5 | O14: =ROUND(H14/$G$4,1) -> 41.9 | P14: =IF(G14="",0,IF(S13="",ROUND((H14-F14)/$G$4,0),O14-N14)) -> 38.4 | Q14: =IF(ROUND(P14*$G$4,0)<G14,"ΚΛΕΒΕΙ",ROUND(P14*$G$4,0)) -> 1200 | R14: =ΣΤΟΙΧΕΙΑ!F2+27 -> 40905 | S14: 15 | T14: =IF(S14="",0,IF(G14="",ROUND(N14-S14,1),ROUND(O14-S14,1))) -> 26.9 | U14: =ROUND(T14*$G$4,1) -> 840.6 | V14: =ROUND(U14*M14,0) -> 700 | X14: 34.5 | Y14: =X14-X13 -> 2.2 | Z14: 600 | AA14: =Z14-Z13 -> 50 | AB14: 30
A15: =A14+1 -> 3 | B15: =ΣΤΟΙΧΕΙΑ!F3 -> 40909 | D15: =IF(G15="","",ΣΤΟΙΧΕΙΑ!$C$14) | F15: =IF(S14="",H14,ROUND(S14*$G$4,0)) -> 469 | H15: =SUM(F15:G15) -> 469 | I15: =ROUND(F15*M14,1) -> 390.5 | K15: =I15+J15 -> 390.5 | L15: =IF(G15="",0,ROUND(J15/G15,3)) -> 0 | M15: =IF(H15=0,0,ROUND(K15/H15,4)) -> 0.8326 | N15: =ROUND(F15/$G$4,1) -> 15 | O15: =ROUND(H15/$G$4,1) -> 15 | P15: =IF(G15="",0,IF(S14="",ROUND((H15-F15)/$G$4,0),O15-N15)) -> 0 | Q15: =IF(ROUND(P15*$G$4,0)<G15,"ΚΛΕΒΕΙ",ROUND(P15*$G$4,0)) -> 0 | R15: =ΣΤΟΙΧΕΙΑ!F3+27 -> 40936 | S15: 0 | T15: =IF(S15="",0,IF(G15="",ROUND(N15-S15,1),ROUND(O15-S15,1))) -> 15 | U15: =ROUND(T15*$G$4,1) -> 468.8 | V15: =ROUND(U15*M15,0) -> 390 | X15: 36.5 | Y15: =X15-X14 -> 2 | Z15: 650 | AA15: =Z15-Z14 -> 50 | AB15: 32.5
A16: =A15+1 -> 4 | B16: =ΣΤΟΙΧΕΙΑ!F4 -> 40940 | D16: =IF(G16="","",ΣΤΟΙΧΕΙΑ!$C$14) | F16: =IF(S15="",H15,ROUND(S15*$G$4,0)) -> 0 | H16: =SUM(F16:G16) -> 0 | I16: =ROUND(F16*M15,1) -> 0 | K16: =I16+J16 -> 0 | L16: =IF(G16="",0,ROUND(J16/G16,3)) -> 0 | M16: =IF(H16=0,0,ROUND(K16/H16,4)) -> 0 | N16: =ROUND(F16/$G$4,1) -> 0 | O16: =ROUND(H16/$G$4,1) -> 0 | P16: =IF(G16="",0,IF(S15="",ROUND((H16-F16)/$G$4,0),O16-N16)) -> 0 | Q16: =IF(ROUND(P16*$G$4,0)<G16,"ΚΛΕΒΕΙ",ROUND(P16*$G$4,0)) -> 0 | R16: =ΣΤΟΙΧΕΙΑ!F4+27 -> 40967 | S16: 0 | T16: =IF(S16="",0,IF(G16="",ROUND(N16-S16,1),ROUND(O16-S16,1))) -> 0 | U16: =ROUND(T16*$G$4,1) -> 0 | V16: =ROUND(U16*M16,0) -> 0 | X16: 38.7 | Y16: =X16-X15 -> 2.2 | Z16: 700 | AA16: =Z16-Z15 -> 50 | AB16: 35
A17: =A16+1 -> 5 | B17: =ΣΤΟΙΧΕΙΑ!F5 -> 40969 | D17: =IF(G17="","",ΣΤΟΙΧΕΙΑ!$C$14) | F17: =IF(S16="",H16,ROUND(S16*$G$4,0)) -> 0 | H17: =SUM(F17:G17) -> 0 | I17: =ROUND(F17*M16,1) -> 0 | K17: =I17+J17 -> 0 | L17: =IF(G17="",0,ROUND(J17/G17,3)) -> 0 | M17: =IF(H17=0,0,ROUND(K17/H17,4)) -> 0 | N17: =ROUND(F17/$G$4,1) -> 0 | O17: =ROUND(H17/$G$4,1) -> 0 | P17: =IF(G17="",0,IF(S16="",ROUND((H17-F17)/$G$4,0),O17-N17)) -> 0 | Q17: =IF(ROUND(P17*$G$4,0)<G17,"ΚΛΕΒΕΙ",ROUND(P17*$G$4,0)) -> 0 | R17: =ΣΤΟΙΧΕΙΑ!F5+27 -> 40996 | S17: 0 | T17: =IF(S17="",0,IF(G17="",ROUND(N17-S17,1),ROUND(O17-S17,1))) -> 0 | U17: =ROUND(T17*$G$4,1) -> 0 | V17: =ROUND(U17*M17,0) -> 0 | X17: 41.3 | Y17: =X17-X16 -> 2.6 | Z17: 750 | AA17: =Z17-Z16 -> 50 | AB17: 37.5
A18: =A17+1 -> 6 | B18: =ΣΤΟΙΧΕΙΑ!F6 -> 41000 | D18: =IF(G18="","",ΣΤΟΙΧΕΙΑ!$C$14) | F18: =IF(S17="",H17,ROUND(S17*$G$4,0)) -> 0 | H18: =SUM(F18:G18) -> 0 | I18: =ROUND(F18*M17,1) -> 0 | K18: =I18+J18 -> 0 | L18: =IF(G18="",0,ROUND(J18/G18,3)) -> 0 | M18: =IF(H18=0,0,ROUND(K18/H18,4)) -> 0 | N18: =ROUND(F18/$G$4,1) -> 0 | O18: =ROUND(H18/$G$4,1) -> 0 | P18: =IF(G18="",0,IF(S17="",ROUND((H18-F18)/$G$4,0),O18-N18)) -> 0 | Q18: =IF(ROUND(P18*$G$4,0)<G18,"ΚΛΕΒΕΙ",ROUND(P18*$G$4,0)) -> 0 | R18: =ΣΤΟΙΧΕΙΑ!F6+27 -> 41027 | S18: 0 | T18: =IF(S18="",0,IF(G18="",ROUND(N18-S18,1),ROUND(O18-S18,1))) -> 0 | U18: =ROUND(T18*$G$4,1) -> 0 | V18: =ROUND(U18*M18,0) -> 0 | X18: 43.3 | Y18: =X18-X17 -> 2 | Z18: 800 | AA18: =Z18-Z17 -> 50 | AB18: 40
A19: =A18+1 -> 7 | B19: =ΣΤΟΙΧΕΙΑ!F7 -> 41030 | D19: =IF(G19="","",ΣΤΟΙΧΕΙΑ!$C$14) | F19: =IF(S18="",H18,ROUND(S18*$G$4,0)) -> 0 | H19: =SUM(F19:G19) -> 0 | I19: =ROUND(F19*M18,1) -> 0 | K19: =I19+J19 -> 0 | L19: =IF(G19="",0,ROUND(J19/G19,3)) -> 0 | M19: =IF(H19=0,0,ROUND(K19/H19,4)) -> 0 | N19: =ROUND(F19/$G$4,1) -> 0 | O19: =ROUND(H19/$G$4,1) -> 0 | P19: =IF(G19="",0,IF(S18="",ROUND((H19-F19)/$G$4,0),O19-N19)) -> 0 | Q19: =IF(ROUND(P19*$G$4,0)<G19,"ΚΛΕΒΕΙ",ROUND(P19*$G$4,0)) -> 0 | R19: =ΣΤΟΙΧΕΙΑ!F7+27 -> 41057 | S19: 0 | T19: =IF(S19="",0,IF(G19="",ROUND(N19-S19,1),ROUND(O19-S19,1))) -> 0 | U19: =ROUND(T19*$G$4,1) -> 0 | V19: =ROUND(U19*M19,0) -> 0 | X19: 45.5 | Y19: =X19-X18 -> 2.2 | Z19: 850 | AA19: =Z19-Z18 -> 50 | AB19: 42.5
A20: =A19+1 -> 8 | B20: =ΣΤΟΙΧΕΙΑ!F8 -> 41061 | D20: =IF(G20="","",ΣΤΟΙΧΕΙΑ!$C$14) | F20: =IF(S19="",H19,ROUND(S19*$G$4,0)) -> 0 | H20: =SUM(F20:G20) -> 0 | I20: =ROUND(F20*M19,1) -> 0 | K20: =I20+J20 -> 0 | L20: =IF(G20="",0,ROUND(J20/G20,3)) -> 0 | M20: =IF(H20=0,0,ROUND(K20/H20,4)) -> 0 | N20: =ROUND(F20/$G$4,1) -> 0 | O20: =ROUND(H20/$G$4,1) -> 0 | P20: =IF(G20="",0,IF(S19="",ROUND((H20-F20)/$G$4,0),O20-N20)) -> 0 | Q20: =IF(ROUND(P20*$G$4,0)<G20,"ΚΛΕΒΕΙ",ROUND(P20*$G$4,0)) -> 0 | R20: =ΣΤΟΙΧΕΙΑ!F8+27 -> 41088 | S20: 0 | T20: =IF(S20="",0,IF(G20="",ROUND(N20-S20,1),ROUND(O20-S20,1))) -> 0 | U20: =ROUND(T20*$G$4,1) -> 0 | V20: =ROUND(U20*M20,0) -> 0 | X20: 48 | Y20: =X20-X19 -> 2.5 | Z20: 900 | AA20: =Z20-Z19 -> 50 | AB20: 45
A21: =A20+1 -> 9 | B21: =ΣΤΟΙΧΕΙΑ!F9 -> 41091 | D21: =IF(G21="","",ΣΤΟΙΧΕΙΑ!$C$14) | F21: =IF(S20="",H20,ROUND(S20*$G$4,0)) -> 0 | H21: =SUM(F21:G21) -> 0 | I21: =ROUND(F21*M20,1) -> 0 | K21: =I21+J21 -> 0 | L21: =IF(G21="",0,ROUND(J21/G21,3)) -> 0 | M21: =IF(H21=0,0,ROUND(K21/H21,4)) -> 0 | N21: =ROUND(F21/$G$4,1) -> 0 | O21: =ROUND(H21/$G$4,1) -> 0 | P21: =IF(G21="",0,IF(S20="",ROUND((H21-F21)/$G$4,0),O21-N21)) -> 0 | Q21: =IF(ROUND(P21*$G$4,0)<G21,"ΚΛΕΒΕΙ",ROUND(P21*$G$4,0)) -> 0 | R21: =ΣΤΟΙΧΕΙΑ!F9+27 -> 41118 | S21: 0 | T21: =IF(S21="",0,IF(G21="",ROUND(N21-S21,1),ROUND(O21-S21,1))) -> 0 | U21: =ROUND(T21*$G$4,1) -> 0 | V21: =ROUND(U21*M21,0) -> 0 | X21: 50.3 | Y21: =X21-X20 -> 2.3 | Z21: 950 | AA21: =Z21-Z20 -> 50 | AB21: 47.5
A22: =A21+1 -> 10 | B22: =ΣΤΟΙΧΕΙΑ!F10 -> 41122 | D22: =IF(G22="","",ΣΤΟΙΧΕΙΑ!$C$14) | F22: =IF(S21="",H21,ROUND(S21*$G$4,0)) -> 0 | H22: =SUM(F22:G22) -> 0 | I22: =ROUND(F22*M21,1) -> 0 | K22: =I22+J22 -> 0 | L22: =IF(G22="",0,ROUND(J22/G22,3)) -> 0 | M22: =IF(H22=0,0,ROUND(K22/H22,4)) -> 0 | N22: =ROUND(F22/$G$4,1) -> 0 | O22: =ROUND(H22/$G$4,1) -> 0 | P22: =IF(G22="",0,IF(S21="",ROUND((H22-F22)/$G$4,0),O22-N22)) -> 0 | Q22: =IF(ROUND(P22*$G$4,0)<G22,"ΚΛΕΒΕΙ",ROUND(P22*$G$4,0)) -> 0 | R22: =ΣΤΟΙΧΕΙΑ!F10+27 -> 41149 | S22: 0 | T22: =IF(S22="",0,IF(G22="",ROUND(N22-S22,1),ROUND(O22-S22,1))) -> 0 | U22: =ROUND(T22*$G$4,1) -> 0 | V22: =ROUND(U22*M22,0) -> 0 | X22: 52.5 | Y22: =X22-X21 -> 2.2 | Z22: 1000 | AA22: =Z22-Z21 -> 50 | AB22: 50
A23: =A22+1 -> 11 | B23: =ΣΤΟΙΧΕΙΑ!F11 -> 41153 | D23: =IF(G23="","",ΣΤΟΙΧΕΙΑ!$C$14) | F23: =IF(S22="",H22,ROUND(S22*$G$4,0)) -> 0 | H23: =SUM(F23:G23) -> 0 | I23: =ROUND(F23*M22,1) -> 0 | K23: =I23+J23 -> 0 | L23: =IF(G23="",0,ROUND(J23/G23,3)) -> 0 | M23: =IF(H23=0,0,ROUND(K23/H23,4)) -> 0 | N23: =ROUND(F23/$G$4,1) -> 0 | O23: =ROUND(H23/$G$4,1) -> 0 | P23: =IF(G23="",0,IF(S22="",ROUND((H23-F23)/$G$4,0),O23-N23)) -> 0 | Q23: =IF(ROUND(P23*$G$4,0)<G23,"ΚΛΕΒΕΙ",ROUND(P23*$G$4,0)) -> 0 | R23: =ΣΤΟΙΧΕΙΑ!F11+27 -> 41180 | S23: 0 | T23: =IF(S23="",0,IF(G23="",ROUND(N23-S23,1),ROUND(O23-S23,1))) -> 0 | U23: =ROUND(T23*$G$4,1) -> 0 | V23: =ROUND(U23*M23,0) -> 0 | X23: 54.5 | Y23: =X23-X22 -> 2 | Z23: 1050 | AA23: =Z23-Z22 -> 50 | AB23: 52.5
A24: =A23+1 -> 12 | B24: =ΣΤΟΙΧΕΙΑ!F12 -> 41183 | D24: =IF(G24="","",ΣΤΟΙΧΕΙΑ!$C$14) | F24: =IF(S23="",H23,ROUND(S23*$G$4,0)) -> 0 | H24: =SUM(F24:G24) -> 0 | I24: =ROUND(F24*M23,1) -> 0 | K24: =I24+J24 -> 0 | L24: =IF(G24="",0,ROUND(J24/G24,3)) -> 0 | M24: =IF(H24=0,0,ROUND(K24/H24,4)) -> 0 | N24: =ROUND(F24/$G$4,1) -> 0 | O24: =ROUND(H24/$G$4,1) -> 0 | P24: =IF(G24="",0,IF(S23="",ROUND((H24-F24)/$G$4,0),O24-N24)) -> 0 | Q24: =IF(ROUND(P24*$G$4,0)<G24,"ΚΛΕΒΕΙ",ROUND(P24*$G$4,0)) -> 0 | R24: =ΣΤΟΙΧΕΙΑ!F12+27 -> 41210 | S24: 0 | T24: =IF(S24="",0,IF(G24="",ROUND(N24-S24,1),ROUND(O24-S24,1))) -> 0 | U24: =ROUND(T24*$G$4,1) -> 0 | V24: =ROUND(U24*M24,0) -> 0 | X24: 56.7 | Y24: =X24-X23 -> 2.2 | Z24: 1100 | AA24: =Z24-Z23 -> 50 | AB24: 55
A25: =A24+1 -> 13 | B25: =ΣΤΟΙΧΕΙΑ!F13 -> 41214 | D25: =IF(G25="","",ΣΤΟΙΧΕΙΑ!$C$14) | F25: =IF(S24="",H24,ROUND(S24*$G$4,0)) -> 0 | H25: =SUM(F25:G25) -> 0 | I25: =ROUND(F25*M24,1) -> 0 | K25: =I25+J25 -> 0 | L25: =IF(G25="",0,ROUND(J25/G25,3)) -> 0 | M25: =IF(H25=0,0,ROUND(K25/H25,4)) -> 0 | N25: =ROUND(F25/$G$4,1) -> 0 | O25: =ROUND(H25/$G$4,1) -> 0 | P25: =IF(G25="",0,IF(S24="",ROUND((H25-F25)/$G$4,0),O25-N25)) -> 0 | Q25: =IF(ROUND(P25*$G$4,0)<G25,"ΚΛΕΒΕΙ",ROUND(P25*$G$4,0)) -> 0 | R25: =ΣΤΟΙΧΕΙΑ!F13+27 -> 41241 | S25: 0 | T25: =IF(S25="",0,IF(G25="",ROUND(N25-S25,1),ROUND(O25-S25,1))) -> 0 | U25: =ROUND(T25*$G$4,1) -> 0 | V25: =ROUND(U25*M25,0) -> 0 | X25: 59 | Y25: =X25-X24 -> 2.3 | Z25: 1150 | AA25: =Z25-Z24 -> 50 | AB25: 57.5
A26: =A25+1 -> 14 | B26: =ΣΤΟΙΧΕΙΑ!F14 -> 41244 | D26: =IF(G26="","",ΣΤΟΙΧΕΙΑ!$C$14) | F26: =IF(S25="",H25,ROUND(S25*$G$4,0)) -> 0 | H26: =SUM(F26:G26) -> 0 | I26: =ROUND(F26*M25,1) -> 0 | K26: =I26+J26 -> 0 | L26: =IF(G26="",0,ROUND(J26/G26,3)) -> 0 | M26: =IF(H26=0,0,ROUND(K26/H26,4)) -> 0 | N26: =ROUND(F26/$G$4,1) -> 0 | O26: =ROUND(H26/$G$4,1) -> 0 | P26: =IF(G26="",0,IF(S25="",ROUND((H26-F26)/$G$4,0),O26-N26)) -> 0 | Q26: =IF(ROUND(P26*$G$4,0)<G26,"ΚΛΕΒΕΙ",ROUND(P26*$G$4,0)) -> 0 | R26: =ΣΤΟΙΧΕΙΑ!F14+27 -> 41271 | S26: 0 | T26: =IF(S26="",0,IF(G26="",ROUND(N26-S26,1),ROUND(O26-S26,1))) -> 0 | U26: =ROUND(T26*$G$4,1) -> 0 | V26: =ROUND(U26*M26,0) -> 0 | X26: 61 | Y26: =X26-X25 -> 2 | Z26: 1200 | AA26: =Z26-Z25 -> 50 | AB26: 60
... A31: =A30+1 -> 19 | B31: =ΣΤΟΙΧΕΙΑ!F19 -> 41395 | D31: =IF(G31="","",ΣΤΟΙΧΕΙΑ!$C$14) | F31: =IF(S30="",H30,ROUND(S30*$G$4,0)) -> 0 | H31: =SUM(F31:G31) -> 0 | I31: =ROUND(F31*M30,1) -> 0 | K31: =I31+J31 -> 0 | L31: =IF(G31="",0,ROUND(J31/G31,3)) -> 0 | M31: =IF(H31=0,0,ROUND(K31/H31,4)) -> 0 | N31: =ROUND(F31/$G$4,1) -> 0 | O31: =ROUND(H31/$G$4,1) -> 0 | P31: =IF(G31="",0,IF(S30="",ROUND((H31-F31)/$G$4,0),O31-N31)) -> 0 | Q31: =IF(ROUND(P31*$G$4,0)<G31,"ΚΛΕΒΕΙ",ROUND(P31*$G$4,0)) -> 0 | R31: =ΣΤΟΙΧΕΙΑ!F19+27 -> 41422 | S31: 0 | T31: =IF(S31="",0,IF(G31="",ROUND(N31-S31,1),ROUND(O31-S31,1))) -> 0 | U31: =ROUND(T31*$G$4,1) -> 0 | V31: =ROUND(U31*M31,0) -> 0 | X31: 73.3 | Y31: =X31-X30 -> 2.8 | Z31: 1450 | AA31: =Z31-Z30 -> 50 | AB31: 72.5
A32: =A31+1 -> 20 | B32: =ΣΤΟΙΧΕΙΑ!F20 -> 41426 | D32: =IF(G32="","",ΣΤΟΙΧΕΙΑ!$C$14) | F32: =IF(S31="",H31,ROUND(S31*$G$4,0)) -> 0 | H32: =SUM(F32:G32) -> 0 | I32: =ROUND(F32*M31,1) -> 0 | K32: =I32+J32 -> 0 | L32: =IF(G32="",0,ROUND(J32/G32,3)) -> 0 | M32: =IF(H32=0,0,ROUND(K32/H32,4)) -> 0 | N32: =ROUND(F32/$G$4,1) -> 0 | O32: =ROUND(H32/$G$4,1) -> 0 | P32: =IF(G32="",0,IF(S31="",ROUND((H32-F32)/$G$4,0),O32-N32)) -> 0 | Q32: =IF(ROUND(P32*$G$4,0)<G32,"ΚΛΕΒΕΙ",ROUND(P32*$G$4,0)) -> 0 | R32: =ΣΤΟΙΧΕΙΑ!F20+27 -> 41453 | T32: =IF(S32="",0,IF(G32="",ROUND(N32-S32,1),ROUND(O32-S32,1))) -> 0 | U32: =ROUND(T32*$G$4,1) -> 0 | V32: =ROUND(U32*M32,0) -> 0 | X32: 75.5 | Y32: =X32-X31 -> 2.2 | Z32: 1500 | AA32: =Z32-Z31 -> 50 | AB32: 75
A33: =A32+1 -> 21 | B33: =ΣΤΟΙΧΕΙΑ!F21 -> 41456 | D33: =IF(G33="","",ΣΤΟΙΧΕΙΑ!$C$14) | F33: =IF(S32="",H32,ROUND(S32*$G$4,0)) -> 0 | H33: =SUM(F33:G33) -> 0 | I33: =ROUND(F33*M32,1) -> 0 | K33: =I33+J33 -> 0 | L33: =IF(G33="",0,ROUND(J33/G33,3)) -> 0 | M33: =IF(H33=0,0,ROUND(K33/H33,4)) -> 0 | N33: =ROUND(F33/$G$4,1) -> 0 | O33: =ROUND(H33/$G$4,1) -> 0 | P33: =IF(G33="",0,IF(S32="",ROUND((H33-F33)/$G$4,0),O33-N33)) -> 0 | Q33: =IF(ROUND(P33*$G$4,0)<G33,"ΚΛΕΒΕΙ",ROUND(P33*$G$4,0)) -> 0 | R33: =ΣΤΟΙΧΕΙΑ!F21+27 -> 41483 | S33: 0 | T33: =IF(S33="",0,IF(G33="",ROUND(N33-S33,1),ROUND(O33-S33,1))) -> 0 | U33: =ROUND(T33*$G$4,1) -> 0 | V33: =ROUND(U33*M33,0) -> 0 | X33: 78.3 | Y33: =X33-X32 -> 2.8 | Z33: 1550 | AA33: =Z33-Z32 -> 50 | AB33: 77.5
A34: Έλεγχος Κόστους Πετρελαίου που Αγοράστηκε: | J34: =SUM(J13:J33) -> 1091 | K34: σε σχέση με το Κόστος Πετρελαίου που Χρεώθηκε στους Ενοίκους + το Απλήρωτο Υπόλοιπο της Δεξαμενής: | V34: =SUM(V13:V33) -> 1090 | X34: 81 | Y34: =X34-X33 -> 2.7 | Z34: 1600 | AA34: =Z34-Z33 -> 50 | AB34: 80
X35: 83.5 | Y35: =X35-X34 -> 2.5 | Z35: 1650 | AA35: =Z35-Z34 -> 50 | AB35: 82.5
X36: 86 | Y36: =X36-X35 -> 2.5 | Z36: 1700 | AA36: =Z36-Z35 -> 50 | AB36: 85
X37: 89 | Y37: =X37-X36 -> 3 | Z37: 1750 | AA37: =Z37-Z36 -> 50 | AB37: 87.5
X38: 92 | Y38: =X38-X37 -> 3 | Z38: 1800 | AA38: =Z38-Z37 -> 50 | AB38: 90
X39: 95.5 | Y39: =X39-X38 -> 3.5 | Z39: 1850 | AA39: =Z39-Z38 -> 50 | AB39: 92.5
X40: 98.5 | Y40: =X40-X39 -> 3 | Z40: 1900 | AA40: =Z40-Z39 -> 50 | AB40: 95
X41: 101.5 | Y41: =X41-X40 -> 3 | Z41: 1950 | AA41: =Z41-Z40 -> 50 | AB41: 97.5
X42: 106 | Y42: =X42-X41 -> 4.5 | Z42: 2000 | AA42: =Z42-Z41 -> 50 | AB42: 100
X43: 111.3 | Y43: =X43-X42 -> 5.3 | Z43: 2050 | AA43: =Z43-Z42 -> 50 | AB43: 102.5
X44: 118 | Y44: =X44-X43 -> 6.7 | Z44: 2100 | AA44: =Z44-Z43 -> 50 | AB44: 105

Sheet Ώρες
D1: =ΣΤΟΙΧΕΙΑ!C15 -> Μετρητές & Ώρες: | J1: =ΣΤΟΙΧΕΙΑ!C12 -> Διευθύνση 123
A2: ΕΝΔΕΙΞΕΙΣ ΜΕΤΡΗΤΩΝ ΑΥΤΟΝΟΜΗΣ ΘΕΡΜΑΝΣΗΣ ΑΝΑΚΕΦΑΛΑΙΩΤΙΚΑ
A3: Α/Α | B3: Διαμέρισμα | C3: Μετρητής | D3: =INDIRECT(ADDRESS(A4,6,3,,"ΣΤΟΙΧΕΙΑ"))+27 -> 40875 | E3: =INDIRECT(ADDRESS(B4,6,3,,"ΣΤΟΙΧΕΙΑ"))+27 -> 40905 | F3: =INDIRECT(ADDRESS(C4,6,3,,"ΣΤΟΙΧΕΙΑ"))+27 -> 40936 | G3: =INDIRECT(ADDRESS(D4,6,3,,"ΣΤΟΙΧΕΙΑ"))+27 -> 40967 | H3: =INDIRECT(ADDRESS(E4,6,3,,"ΣΤΟΙΧΕΙΑ"))+27 -> 40996 | I3: =INDIRECT(ADDRESS(F4,6,3,,"ΣΤΟΙΧΕΙΑ"))+27 -> 41027 | J3: =INDIRECT(ADDRESS(G4,6,3,,"ΣΤΟΙΧΕΙΑ"))+27 -> 41057 | K3: =INDIRECT(ADDRESS(H4,6,3,,"ΣΤΟΙΧΕΙΑ"))+27 -> 41088 | ... P3: =INDIRECT(ADDRESS(M4,6,3,,"ΣΤΟΙΧΕΙΑ"))+27 -> 41241
A4: 1 | B4: =A4+1 -> 2 | C4: =B4+1 -> 3 | D4: =C4+1 -> 4 | E4: =D4+1 -> 5 | F4: =E4+1 -> 6 | G4: =F4+1 -> 7 | H4: =G4+1 -> 8 | I4: =H4+1 -> 9 | ... P4: =O4+1 -> 16
A5: =IF(B5="","",1) -> 1 | B5: =IF(Διαμερίσματα!B6="","",Διαμερίσματα!B6) -> Κ1 | D5: 0 | E5: 0 | F5: 0
A6: =IF(B6="","",A5+1) -> 2 | B6: =IF(Διαμερίσματα!B7="","",Διαμερίσματα!B7) -> Κ2 | D6: 1520 | E6: 1520 | F6: 1520
A7: =IF(B7="","",A6+1) -> 3 | B7: =IF(Διαμερίσματα!B8="","",Διαμερίσματα!B8) -> Κ3 | D7: 1584 | E7: 1683 | F7: 1684
A8: =IF(B8="","",A7+1) -> 4 | B8: =IF(Διαμερίσματα!B9="","",Διαμερίσματα!B9) -> Α1 | D8: 1318 | E8: 1374 | F8: 1374
A9: =IF(B9="","",A8+1) -> 5 | B9: =IF(Διαμερίσματα!B10="","",Διαμερίσματα!B10) -> Α2 | D9: 1706 | E9: 1773 | F9: 1773
A10: =IF(B10="","",A9+1) -> 6 | B10: =IF(Διαμερίσματα!B11="","",Διαμερίσματα!B11) -> Α3 | D10: 0 | E10: 0 | F10: 0
A11: =IF(B11="","",A10+1) -> 7 | B11: =IF(Διαμερίσματα!B12="","",Διαμερίσματα!B12) -> Α4 | D11: 0 | E11: 0 | F11: 0
A12: =IF(B12="","",A11+1) -> 8 | B12: =IF(Διαμερίσματα!B13="","",Διαμερίσματα!B13) -> Β1 | D12: 152 | E12: 173 | F12: 173
A13: =IF(B13="","",A12+1) -> 9 | B13: =IF(Διαμερίσματα!B14="","",Διαμερίσματα!B14) -> Β2 | D13: 380 | E13: 392 | F13: 392
A14: =IF(B14="","",A13+1) -> 10 | B14: =IF(Διαμερίσματα!B15="","",Διαμερίσματα!B15) -> Β3 | D14: 682 | E14: 742 | F14: 742
A15: =IF(B15="","",A14+1) -> 11 | B15: =IF(Διαμερίσματα!B16="","",Διαμερίσματα!B16) -> Β4 | D15: 1528 | E15: 1600 | F15: 1600
A16: =IF(B16="","",A15+1) -> 12 | B16: =IF(Διαμερίσματα!B17="","",Διαμερίσματα!B17) -> Γ1 | D16: 0 | E16: 0 | F16: 0
A17: =IF(B17="","",A16+1) -> 13 | B17: =IF(Διαμερίσματα!B18="","",Διαμερίσματα!B18) -> Γ2 | D17: 0 | E17: 0 | F17: 0
... A26: =IF(B26="","",A25+1) -> 22 | B26: =IF(Διαμερίσματα!B27="","",Διαμερίσματα!B27) -> Ε3 | D26: 0 | E26: 0 | F26: 0
A28: ΩΡΕΣ ΛΕΙΤΟΥΡΓΙΑΣ ΑΝΑ ΔΙΑΜΕΡΙΣΜΑ & ΜΗΝΑ
A29: =A3 -> Α/Α | B29: =B3 -> Διαμέρισμα | C29: =C3 -> Μετρητής | D29: =INDIRECT(ADDRESS(A4,6,3,,"ΣΤΟΙΧΕΙΑ")) -> 40848 | E29: =INDIRECT(ADDRESS(B4,6,3,,"ΣΤΟΙΧΕΙΑ")) -> 40878 | F29: =INDIRECT(ADDRESS(C4,6,3,,"ΣΤΟΙΧΕΙΑ")) -> 40909 | G29: =INDIRECT(ADDRESS(D4,6,3,,"ΣΤΟΙΧΕΙΑ")) -> 40940 | H29: =INDIRECT(ADDRESS(E4,6,3,,"ΣΤΟΙΧΕΙΑ")) -> 40969 | I29: =INDIRECT(ADDRESS(F4,6,3,,"ΣΤΟΙΧΕΙΑ")) -> 41000 | J29: =INDIRECT(ADDRESS(G4,6,3,,"ΣΤΟΙΧΕΙΑ")) -> 41030 | K29: =INDIRECT(ADDRESS(H4,6,3,,"ΣΤΟΙΧΕΙΑ")) -> 41061 | ... P29: =INDIRECT(ADDRESS(M4,6,3,,"ΣΤΟΙΧΕΙΑ")) -> 41214
A30: =A4 -> 1 | B30: =B4 -> 2 | C30: =C4 -> 3 | D30: =D4 -> 4 | E30: =E4 -> 5 | F30: =F4 -> 6 | G30: =G4 -> 7 | H30: =H4 -> 8 | ... P30: =P4 -> 16
